Workbook

Sheet Instructions
B2: FTB Supply & Production — Data Workbook
B4: This workbook is the data source for the FTB Supply & Production Dashboard.
B6: HOW TO USE
B7: 1. Fill in the yellow cells in 'Project Overview' with your current site-level totals.
B8: 2. Each month, add a new row to 'Monthly History' with that month's production/installation totals per site.
B9: 3. Save this file, then in the dashboard click 'Upload File' and select this workbook (.xlsx).
B10: 4. The dashboard reads both tabs automatically — Project Overview for the current snapshot, and Monthly History for the 6-month projection chart.
B12: COLOR LEGEND
B13: Yellow cells = type your data here
B14: Grey cells = calculated automatically — do not type over these
B15: Light grey/italic = example row — delete or ignore, just shows the expected format
B17: PROJECT OVERVIEW — COLUMN NOTES
... B88: Actual chart, alongside Target Installation vs. Actual Installation.

Sheet Project Overview
A1: FTB Supply & Production — Project Overview
A2: Fill in yellow cells only. Grey cells are auto-calculated — do not overwrite them.
A4: Site | B4: Contract Units | C4: With PO | D4: No PO | E4: PO % | F4: FTB Produced | G4: Installed | H4: Deductions (Punchlist/Awarded/Hold Units) | I4: Available FTB | J4: COCA | K4: Critical Month | L4: Risk Level | M4: Auto Risk (preview) | N4: Notes | O4: Action
A5: Batulao Parkhomes | B5: 2052 | C5: 2019 | D5: =B5-C5 -> 33 | E5: =IFERROR(C5/B5,0) -> 0.98391813 | F5: =SUM('Annual History'!C5:C9)+SUM('Monthly History'!C6:C17) -> 1839 | G5: =SUM('Annual History'!E5:E9)+SUM('Monthly History'!D6:D17) -> 1824 | H5: 0 | I5: =F5-G5-H5 -> 15 | J5: =SUM('Annual History'!G5:G9)+SUM('Monthly History'!L6:L17) -> 1685 | M5: =IF((F5-G5)<100,"Critical",IF((F5-G5)<200,"At Risk","On Track")) -> Critical
A6: Calauan (Alora+Amani) | B6: =830+1390 -> 2220 | C6: 666 | D6: =B6-C6 -> 1554 | E6: =IFERROR(C6/B6,0) -> 0.3 | F6: =SUM('Annual History'!C10)+SUM('Monthly History'!C18:C29) -> 521 | G6: =SUM('Annual History'!E10)+SUM('Monthly History'!D18:D29) -> 416 | H6: 26 | I6: =F6-G6-H6 -> 79 | J6: =SUM('Annual History'!G10)+SUM('Monthly History'!L18:L29) -> 316 | M6: =IF((F6-G6)<100,"Critical",IF((F6-G6)<200,"At Risk","On Track")) -> At Risk
A7: Gentri | B7: 1642 | C7: 1540 | D7: =B7-C7 -> 102 | E7: =IFERROR(C7/B7,0) -> 0.93788063 | F7: =SUM('Annual History'!C11:C13)+SUM('Monthly History'!C30:C41) -> 1379 | G7: =SUM('Annual History'!E11:E13)+SUM('Monthly History'!D30:D41) -> 1287 | H7: 0 | I7: =F7-G7-H7 -> 92 | J7: =SUM('Annual History'!G11:G13)+SUM('Monthly History'!M30:M41) -> 819 | M7: =IF((F7-G7)<100,"Critical",IF((F7-G7)<200,"At Risk","On Track")) -> Critical
A8: Naic | B8: 1943 | C8: 1685 | D8: =B8-C8 -> 258 | E8: =IFERROR(C8/B8,0) -> 0.86721565 | F8: =SUM('Annual History'!C14:C16)+SUM('Monthly History'!C42:C53) -> 1218 | G8: =SUM('Annual History'!E14:E16)+SUM('Monthly History'!D42:D53) -> 1058 | H8: 0 | I8: =F8-G8-H8 -> 160 | J8: =SUM('Annual History'!G14:G16)+SUM('Monthly History'!L42:L53) -> 1026 | M8: =IF((F8-G8)<100,"Critical",IF((F8-G8)<200,"At Risk","On Track")) -> At Risk
A9: The Cove Lipa | B9: 1116 | C9: 1018 | D9: =B9-C9 -> 98 | E9: =IFERROR(C9/B9,0) -> 0.91218638 | F9: =SUM('Annual History'!C17)+SUM('Monthly History'!C54:C65) -> 844 | G9: =SUM('Annual History'!E17)+SUM('Monthly History'!D54:D65) -> 604 | H9: 0 | I9: =F9-G9-H9 -> 240 | J9: =SUM('Annual History'!G17)+SUM('Monthly History'!L54:L65) -> 616 | M9: =IF((F9-G9)<100,"Critical",IF((F9-G9)<200,"At Risk","On Track")) -> On Track
A10: Sights Bay | B10: 2266 | C10: 1540 | D10: =B10-C10 -> 726 | E10: =IFERROR(C10/B10,0) -> 0.67961165 | F10: =SUM('Annual History'!C18:C20)+SUM('Monthly History'!C66:C77) -> 2044 | G10: =SUM('Annual History'!E18:E20)+SUM('Monthly History'!D66:D77) -> 1812 | H10: 0 | I10: =F10-G10-H10 -> 232 | J10: =SUM('Annual History'!G18:G20)+SUM('Monthly History'!L66:L77) -> 1788 | M10: =IF((F10-G10)<100,"Critical",IF((F10-G10)<200,"At Risk","On Track")) -> On Track
A11: Tayabas | B11: 2048 | C11: 1615 | D11: =B11-C11 -> 433 | E11: =IFERROR(C11/B11,0) -> 0.78857422 | F11: =SUM('Annual History'!C21:C23)+SUM('Monthly History'!C78:C89) -> 1450 | G11: =SUM('Annual History'!E21:E23)+SUM('Monthly History'!D78:D89) -> 1274 | H11: 0 | I11: =F11-G11-H11 -> 176 | J11: =SUM('Annual History'!G21:G23)+SUM('Monthly History'!L78:L89) -> 1240 | M11: =IF((F11-G11)<100,"Critical",IF((F11-G11)<200,"At Risk","On Track")) -> At Risk
A12: Batulao Impression | B12: 1054 | C12: 296 | D12: =B12-C12 -> 758 | E12: =IFERROR(C12/B12,0) -> 0.28083491 | F12: =SUM('Annual History'!C24)+SUM('Monthly History'!C90:C101) -> 184 | G12: =SUM('Annual History'!E24+SUM('Monthly History'!D90:D101)) -> 30 | H12: 0 | I12: =F12-G12-H12 -> 154 | J12: =SUM('Annual History'!G24)+SUM('Monthly History'!L90:L101) -> 0 | M12: =IF((F12-G12)<100,"Critical",IF((F12-G12)<200,"At Risk","On Track")) -> At Risk
D13: =B13-C13 -> 0 | E13: =IFERROR(C13/B13,0) -> 0 | I13: =F13-G13-H13 -> 0 | M13: =IF((F13-G13)<100,"Critical",IF((F13-G13)<200,"At Risk","On Track")) -> Critical
D14: =B14-C14 -> 0 | E14: =IFERROR(C14/B14,0) -> 0 | I14: =F14-G14-H14 -> 0 | M14: =IF((F14-G14)<100,"Critical",IF((F14-G14)<200,"At Risk","On Track")) -> Critical
D15: =B15-C15 -> 0 | E15: =IFERROR(C15/B15,0) -> 0 | I15: =F15-G15-H15 -> 0 | M15: =IF((F15-G15)<100,"Critical",IF((F15-G15)<200,"At Risk","On Track")) -> Critical
D16: =B16-C16 -> 0 | E16: =IFERROR(C16/B16,0) -> 0 | I16: =F16-G16-H16 -> 0 | M16: =IF((F16-G16)<100,"Critical",IF((F16-G16)<200,"At Risk","On Track")) -> Critical
D17: =B17-C17 -> 0 | E17: =IFERROR(C17/B17,0) -> 0 | I17: =F17-G17-H17 -> 0 | M17: =IF((F17-G17)<100,"Critical",IF((F17-G17)<200,"At Risk","On Track")) -> Critical
D18: =B18-C18 -> 0 | E18: =IFERROR(C18/B18,0) -> 0 | I18: =F18-G18-H18 -> 0 | M18: =IF((F18-G18)<100,"Critical",IF((F18-G18)<200,"At Risk","On Track")) -> Critical

Sheet Monthly History
A1: FTB Supply & Production — Monthly History
A2: One row per site per month. Add a new row each month — never overwrite past months.
A3: Month format: YYYY-MM (e.g. 2026-07). This feeds the dashboard's 6-month projection chart.
A5: Site | B5: Month | C5: FTB Produced | D5: Installed | E5: Volume Produced m3 (Panels) | F5: Volume Installed m3 | G5: Manpower (Production) | H5: Manpower (Installation) | I5: Manhours (Production) | J5: Manhours (Installation) | K5: Target Installation | L5: COCA | M5: Target FTB Produced
A6: Batulao Parkhomes | B6: 2026-01 | C6: 0 | D6: 14 | E6: 121.489 | F6: 146.5 | I6: 3176 | J6: 525 | K6: 60 | L6: 14 | M6: 60
A7: Batulao Parkhomes | B7: 2026-02 | C7: 8 | D7: 30 | E7: 402.237 | F7: 374.03 | I7: 5112 | J7: 760 | K7: 60 | L7: 102 | M7: 60
A8: Batulao Parkhomes | B8: 2026-03 | C8: 30 | D8: 48 | E8: 497.373 | F8: 543.6 | I8: 6429.87 | J8: 923 | K8: 60 | L8: 81 | M8: 60
A9: Batulao Parkhomes | B9: 2026-04 | C9: 22 | D9: 42 | E9: 518.74 | F9: 517.56 | I9: 5454.94 | J9: 631 | K9: 60 | L9: 82 | M9: 60
A10: Batulao Parkhomes | B10: 2026-05 | C10: 32 | D10: 24 | E10: 485.38 | F10: 510.78 | I10: 5103 | J10: 657 | K10: 60 | L10: 20 | M10: 60
A11: Batulao Parkhomes | B11: 2026-06 | C11: 17 | D11: 49 | E11: 498.43 | F11: 439.42 | I11: 5314 | J11: 828 | K11: 60 | L11: 70 | M11: 60
A12: Batulao Parkhomes | B12: 2026-07 | C12: 4 | D12: 33 | E12: 303.22 | F12: 376.94 | I12: 5252 | J12: 797 | K12: 60 | L12: 4 | M12: 60
A13: Batulao Parkhomes | B13: 2026-08 | C13: 0 | D13: 0
A14: Batulao Parkhomes | B14: 2026-09
A15: Batulao Parkhomes | B15: 2026-10
A16: Batulao Parkhomes | B16: 2026-11
A17: Batulao Parkhomes | B17: 2026-12
A18: Calauan (Alora+Amani) | B18: 2026-01 | C18: 4 | D18: 14 | E18: 0 | F18: 23.71 | I18: 0 | J18: 880 | K18: 0 | L18: 60 | M18: 60
A19: Calauan (Alora+Amani) | B19: 2026-02 | C19: 85 | D19: 0 | E19: 0 | F19: 56.98 | I19: 0 | J19: 264 | K19: 0 | L19: 0 | M19: 60
A20: Calauan (Alora+Amani) | B20: 2026-03 | C20: 40 | D20: 0 | E20: 97.75 | F20: 8.51 | I20: 2640 | J20: 664 | K20: 30 | L20: 0 | M20: 60
A21: Calauan (Alora+Amani) | B21: 2026-04 | C21: 24 | D21: 84 | E21: 689.28 | F21: 644.01 | I21: 8938 | J21: 1250 | K21: 40 | L21: 72 | M21: 60
A22: Calauan (Alora+Amani) | B22: 2026-05 | C22: 12 | D22: 90 | E22: 567.3 | F22: 755.36 | I22: 9475 | J22: 1224 | K22: 60 | L22: 102 | M22: 60
A23: Calauan (Alora+Amani) | B23: 2026-06 | C23: 0 | D23: 64 | E23: 672.15 | F23: 506.18 | I23: 10743 | J23: 1119 | K23: 70 | L23: 44 | M23: 60
A24: Calauan (Alora+Amani) | B24: 2026-07 | C24: 0 | D24: 96 | E24: 527.36 | F24: 672.01 | I24: 12677 | J24: 1074 | K24: 70 | L24: 28 | M24: 60
A25: Calauan (Alora+Amani) | B25: 2026-08
A26: Calauan (Alora+Amani) | B26: 2026-09
A27: Calauan (Alora+Amani) | B27: 2026-10
A28: Calauan (Alora+Amani) | B28: 2026-11
A29: Calauan (Alora+Amani) | B29: 2026-12
A30: Gentri | B30: 2026-01 | C30: 63 | D30: 2 | E30: 68.42 | F30: 68.42 | H30: 0 | I30: 0 | J30: 832 | L30: 2
A31: Gentri | B31: 2026-02 | C31: 20 | D31: 32 | E31: 625.59 | F31: 625.59 | H31: 0 | I31: 0 | J31: 760 | L31: 32
A32: Gentri | B32: 2026-03 | C32: 0 | D32: 72 | E32: 938.37 | F32: 938.37 | H32: 0 | I32: 0 | J32: 872 | L32: 72
A33: Gentri | B33: 2026-04 | C33: 12 | D33: 70 | E33: 478.43 | F33: 478.43 | H33: 0 | I33: 0 | J33: 1072 | L33: 70
A34: Gentri | B34: 2026-05 | C34: 22 | D34: 39 | E34: 561.22 | F34: 561.22 | H34: 0 | I34: 0 | J34: 1000 | L34: 39
A35: Gentri | B35: 2026-06 | C35: 15 | D35: 17 | E35: 226.26 | F35: 226.26 | H35: 0 | I35: 0 | J35: 520 | L35: 17
A36: Gentri | B36: 2026-07 | C36: 7 | D36: 23 | E36: 206.56 | F36: 380.4 | H36: 0 | I36: 0 | J36: 1024 | L36: 20
A37: Gentri | B37: 2026-08
A38: Gentri | B38: 2026-09
A39: Gentri | B39: 2026-10
A40: Gentri | B40: 2026-11
A41: Gentri | B41: 2026-12
...

Sheet Annual History
A1: Annual History — Reference Only (2021–2025)
A2: Historical reference before monthly tracking began. Not read by the dashboard — Monthly History (2026+) is what feeds the live projection.
A4: Site | B4: Year | C4: FTB Produced | D4: Target Installation | E4: Actual Installation | F4: RFIA COCA | G4: COCA
A5: Batulao Parkhomes | B5: 2021 | C5: 104 | E5: 104 | G5: 42
A6: Batulao Parkhomes | B6: 2022 | C6: 585 | E6: 585 | G6: 637
A7: Batulao Parkhomes | B7: 2023 | C7: 291 | E7: 291 | G7: 224
A8: Batulao Parkhomes | B8: 2024 | C8: 296 | E8: 296 | G8: 353
A9: Batulao Parkhomes | B9: 2025 | C9: 450 | E9: 308 | G9: 56
A10: Calauan (Alora+Amani) | B10: 2025 | C10: 356 | E10: 68 | G10: 10
A11: Gentri | B11: 2023 | C11: 469 | E11: 121 | G11: 74
A12: Gentri | B12: 2024 | C12: 356 | E12: 596 | G12: 572
A13: Gentri | B13: 2025 | C13: 415 | E13: 315 | G13: 173
A14: Naic | B14: 2023 | C14: 117 | E14: 0 | G14: 0
A15: Naic | B15: 2024 | C15: 304 | E15: 276 | G15: 186
A16: Naic | B16: 2025 | C16: 469 | E16: 306 | G16: 254
... A23: Tayabas | B23: 2025 | C23: 190 | E23: 408 | G23: 387
A24: Batulao Impression | B24: 2025 | C24: 24
