Workbook

Sheet Instructions
B2: Cement & Aggregates Inventory Monitoring — Housing Projects
B3: Tracks cement, sand, gravel (3/4" and 3/8") and concrete admixture per housing site: current stock, consumption from the m3 of concrete produced (via mix design), new deliveries, critical-stock alerts, a daily-to-monthly consumption forecast and a visual dashboard with % of capacity and days remaining.
B5: HOW TO USE
B6: 1. Settings — check the As-of Date (=TODAY() by default), working days per week/month, the materials (unit, supplier lead time, safety stock), the site list and (optional) non-working holidays.
B7: 2. Mix Design — enter your approved mix design: quantity of each material per 1 m3 of concrete (cement in bags, aggregates in m3, admixture in litres), plus the allowance (waste) %.
B8: 3. Current Inventory (1) — one row per site and material: count date, beginning balance (physical count) and maximum storage capacity.
B9: 4. Consumption Log (2) — every day, record the concrete produced: date, site, mix code and m3. The cement, sand, gravel and admixture used are calculated from the mix design and deducted from stock.
B10: 5. Deliveries (3) — record every delivery receipt as 'Received' (added to stock on its date). Also record purchase orders not yet delivered as 'Scheduled' with the expected date: they are not added to stock, but the monitor and the forecast count them as on order.
B11: 6. Production Plan (5) — declare the planned m3 per working day for each site and mix. This drives the daily usage, days remaining, critical dates and the monthly forecast.
B12: 7. Stock Monitor (4), Forecast (5) and Dashboard (6) are automatic. On the Dashboard, pick a site (or All Sites) in the yellow cell.
B13: Dashboard silo, bins & tank: the cement silo, the 3 aggregate bins and the admixture tank fill up to their % of max storage capacity (bands of 5 %). '– – critical level – –' marks the stock needed for the supplier lead time and '– – reorder level – –' the stock for lead time + safety stock; the badge under each vessel is its status.
B15: COLOUR LEGEND
... B51: Room for 100 site/material rows, 2,000 consumption rows, 1,000 deliveries, 80 plan rows, 20 mix designs and 20 sites. To extend a log, insert rows ABOVE its last row (the named ranges then grow) and copy the grey formula cells down.

Sheet Dashboard
B1: 6 · Inventory Dashboard — Cement, Aggregates & Admixture
B2: ="As of "&TEXT(AsOfDate,"dddd, dd mmmm yyyy")&" · Days are working days ("&WorkDaysWeek&" per week) · Pick a site in the yellow cell" -> As of Saturday, 31 October 2026 · Days are working days (6 per week) · Pick a site in the yellow cell
Q3: CHART DATA & HELPERS (automatic — do not edit)
B4: Site / Project: | C4: All Sites | G4: Worst item status: | H4: =IF(COUNTIFS(SM_Site,SelCrit,SM_Status,"OUT OF STOCK")>0,"OUT OF STOCK",IF(COUNTIFS(SM_Site,SelCrit,SM_Status,"CRITICAL")>0,"CRITICAL",IF(COUNTIFS(SM_Site,SelCrit,SM_Status,"REORDER")>0,"REORDER",IF(COUNTIFS(SM_Site,SelCrit,SM_Status,"OK")>0,"OK","NO DATA")))) -> NO DATA | J4: Critical / out: | K4: =COUNTIFS(SM_Site,SelCrit,SM_Status,"CRITICAL")+COUNTIFS(SM_Site,SelCrit,SM_Status,"OUT OF STOCK") -> 0 | L4: To reorder: | M4: =COUNTIFS(SM_Site,SelCrit,SM_Status,"REORDER") -> 0 | Q4: Site criteria | R4: =IF(OR($C$4="",$C$4="All Sites"),"*",$C$4) -> *
B6: =B14&" ("&C14&")" -> Cement (bags) | C6: =B15&" ("&C15&")" -> Sand (m3) | E6: =B16&" ("&C16&")" -> Gravel 3/4" (m3) | G6: =B17&" ("&C17&")" -> Gravel 3/8" (m3) | I6: =B18&" ("&C18&")" -> Admixture (L) | K6: Planned Production (concrete)
B7: =IF(ISNUMBER(H14),H14,"–") -> – | C7: =IF(ISNUMBER(H15),H15,"–") -> – | E7: =IF(ISNUMBER(H16),H16,"–") -> – | G7: =IF(ISNUMBER(H17),H17,"–") -> – | I7: =IF(ISNUMBER(H18),H18,"–") -> – | K7: =SUMIFS(PP_Vol,PP_Site,SelCrit) -> 0
B9: =IF(ISNUMBER(L14),IF($R$4="*","Earliest out ≈ ","Stock-out ≈ ")&TEXT(L14,"ddd dd-mmm"),IF(L14="OUT","OUT OF STOCK now",IF(M14="NO DATA","Not set up yet","No usage declared"))) -> Not set up yet | C9: =IF(ISNUMBER(L15),IF($R$4="*","Earliest out ≈ ","Stock-out ≈ ")&TEXT(L15,"ddd dd-mmm"),IF(L15="OUT","OUT OF STOCK now",IF(M15="NO DATA","Not set up yet","No usage declared"))) -> Not set up yet | E9: =IF(ISNUMBER(L16),IF($R$4="*","Earliest out ≈ ","Stock-out ≈ ")&TEXT(L16,"ddd dd-mmm"),IF(L16="OUT","OUT OF STOCK now",IF(M16="NO DATA","Not set up yet","No usage declared"))) -> Not set up yet | G9: =IF(ISNUMBER(L17),IF($R$4="*","Earliest out ≈ ","Stock-out ≈ ")&TEXT(L17,"ddd dd-mmm"),IF(L17="OUT","OUT OF STOCK now",IF(M17="NO DATA","Not set up yet","No usage declared"))) -> Not set up yet | I9: =IF(ISNUMBER(L18),IF($R$4="*","Earliest out ≈ ","Stock-out ≈ ")&TEXT(L18,"ddd dd-mmm"),IF(L18="OUT","OUT OF STOCK now",IF(M18="NO DATA","Not set up yet","No usage declared"))) -> Not set up yet | K9: ="≈ "&TEXT(K7*WorkDaysMonth,"#,##0")&" m3 per month ("&WorkDaysMonth&" working days)" -> ≈ 0 m3 per month (26 working days)
B10: =TEXT(D14,"#,##0")&" "&C14&IF(ISNUMBER(F14)," · "&TEXT(F14,"0%")&" full","") -> 0 bags | C10: =TEXT(D15,"#,##0")&" "&C15&IF(ISNUMBER(F15)," · "&TEXT(F15,"0%")&" full","") -> 0 m3 | E10: =TEXT(D16,"#,##0")&" "&C16&IF(ISNUMBER(F16)," · "&TEXT(F16,"0%")&" full","") -> 0 m3 | G10: =TEXT(D17,"#,##0")&" "&C17&IF(ISNUMBER(F17)," · "&TEXT(F17,"0%")&" full","") -> 0 m3 | I10: =TEXT(D18,"#,##0")&" "&C18&IF(ISNUMBER(F18)," · "&TEXT(F18,"0%")&" full","") -> 0 L | K10: ="Actual, last 7 days: "&TEXT(SUMIFS(Con_Vol,Con_Site,SelCrit,Con_Date,">"&(AsOfDate-7),Con_Date,"<="&AsOfDate)/MAX(1,NETWORKDAYS.INTL(AsOfDate-6,AsOfDate,WeekendMask,Holidays)),"#,##0.0")&" m3/day" -> Actual, last 7 days: 0.0 m3/day
B11: =M14 -> NO DATA | C11: =M15 -> NO DATA | E11: =M16 -> NO DATA | G11: =M17 -> NO DATA | I11: =M18 -> NO DATA | K11: =IF(K7>0,"PLAN DECLARED","NO DATA") -> NO DATA
B13: Material | C13: Unit | D13: Current Stock | E13: Max Capacity | F13: % of Capacity | G13: Use / Day | H13: Days Remaining | I13: On Order | J13: Reorder By | K13: Critical On | L13: Stock-out On | M13: Status | N13: Sites Critical / Out | O13: Suggested Order Qty | Q13: Code | R13: Lead (days) | S13: Safety (days) | T13: Reorder level (lead + safety) | U13: Critical level (lead time) | V13: Days remaining (on hand) | W13: % of capacity | X13: Earliest reorder | Y13: Earliest critical | Z13: Earliest stock-out | AA13: Silo/bin fill (of 20 bands) | AB13: Critical mark (band) | AC13: Reorder mark (band)
B14: =INDEX(Mat_Short,1) -> Cement | C14: =INDEX(Mat_Unit,1) -> bags | D14: =SUMIFS(SM_Stock,SM_Site,SelCrit,SM_Mat,$Q14) -> 0 | E14: =SUMIFS(SM_Cap,SM_Site,SelCrit,SM_Mat,$Q14) -> 0 | F14: =IF(E14>0,MAX(0,D14)/E14,"") | G14: =SUMIFS(SM_Rate,SM_Site,SelCrit,SM_Mat,$Q14) -> 0 | H14: =IF(G14>0,MAX(0,D14)/G14,"") | I14: =SUMIFS(SM_OnOrder,SM_Site,SelCrit,SM_Mat,$Q14) -> 0 | J14: =IF($X14>=1000000000,"",IF($X14<=AsOfDate,"NOW",$X14)) | K14: =IF($Y14>=1000000000,"",IF($Y14<=AsOfDate,"NOW",$Y14)) | L14: =IF($Z14>=1000000000,"",IF($Z14<=AsOfDate,"OUT",$Z14)) | M14: =IF(COUNTIFS(SM_Site,SelCrit,SM_Mat,$Q14)=0,"NO DATA",IF(COUNTIFS(SM_Site,SelCrit,SM_Mat,$Q14,SM_Status,"OUT OF STOCK")>0,"OUT OF STOCK",IF(COUNTIFS(SM_Site,SelCrit,SM_Mat,$Q14,SM_Status,"CRITICAL")>0,"CRITICAL",IF(COUNTIFS(SM_Site,SelCrit,SM_Mat,$Q14,SM_Status,"REORDER")>0,"REORDER",IF(COUNTIFS(SM_Site,SelCrit,SM_Mat,$Q14,SM_Status,"OK")>0,"OK","NO USAGE"))))) -> NO DATA | N14: =COUNTIFS(SM_Site,SelCrit,SM_Mat,$Q14,SM_Status,"CRITICAL")+COUNTIFS(SM_Site,SelCrit,SM_Mat,$Q14,SM_Status,"OUT OF STOCK") -> 0 | O14: =SUMIFS(SM_Order,SM_Site,SelCrit,SM_Mat,$Q14) -> 0 | Q14: =INDEX(Mat_Code,1) -> CEM | R14: =INDEX(Mat_Lead,1) -> 3 | S14: =INDEX(Mat_Safety,1) -> 2 | T14: =R14+S14 -> 5 | U14: =R14 -> 3 | V14: =IF(ISNUMBER(H14),H14,0) -> 0 | W14: =IF(ISNUMBER(F14),F14,0) -> 0 | X14: =SUMPRODUCT(MIN(((($C$4=SM_Site)+($R$4="*"))>0)*(SM_Mat=$Q14)*SM_RBn+(1-((($C$4=SM_Site)+($R$4="*"))>0)*(SM_Mat=$Q14))*1000000000)) -> 1000000000 | Y14: =SUMPRODUCT(MIN(((($C$4=SM_Site)+($R$4="*"))>0)*(SM_Mat=$Q14)*SM_CRn+(1-((($C$4=SM_Site)+($R$4="*"))>0)*(SM_Mat=$Q14))*1000000000)) -> 1000000000 | Z14: =SUMPRODUCT(MIN(((($C$4=SM_Site)+($R$4="*"))>0)*(SM_Mat=$Q14)*SM_SOn+(1-((($C$4=SM_Site)+($R$4="*"))>0)*(SM_Mat=$Q14))*1000000000)) -> 1000000000 | AA14: =IF(AND(E14>0,D14>0),MIN(20,MAX(1,ROUND(D14/E14*20,0))),0) -> 0 | AB14: =IF(AND(E14>0,G14>0,R14>0),MIN(20,MAX(1,ROUND(G14*R14/E14*20,0))),0) -> 0 | AC14: =IF(AND(E14>0,G14>0,T14>0),MIN(20,MAX(1,ROUND(G14*T14/E14*20,0))),0) -> 0
B15: =INDEX(Mat_Short,2) -> Sand | C15: =INDEX(Mat_Unit,2) -> m3 | D15: =SUMIFS(SM_Stock,SM_Site,SelCrit,SM_Mat,$Q15) -> 0 | E15: =SUMIFS(SM_Cap,SM_Site,SelCrit,SM_Mat,$Q15) -> 0 | F15: =IF(E15>0,MAX(0,D15)/E15,"") | G15: =SUMIFS(SM_Rate,SM_Site,SelCrit,SM_Mat,$Q15) -> 0 | H15: =IF(G15>0,MAX(0,D15)/G15,"") | I15: =SUMIFS(SM_OnOrder,SM_Site,SelCrit,SM_Mat,$Q15) -> 0 | J15: =IF($X15>=1000000000,"",IF($X15<=AsOfDate,"NOW",$X15)) | K15: =IF($Y15>=1000000000,"",IF($Y15<=AsOfDate,"NOW",$Y15)) | L15: =IF($Z15>=1000000000,"",IF($Z15<=AsOfDate,"OUT",$Z15)) | M15: =IF(COUNTIFS(SM_Site,SelCrit,SM_Mat,$Q15)=0,"NO DATA",IF(COUNTIFS(SM_Site,SelCrit,SM_Mat,$Q15,SM_Status,"OUT OF STOCK")>0,"OUT OF STOCK",IF(COUNTIFS(SM_Site,SelCrit,SM_Mat,$Q15,SM_Status,"CRITICAL")>0,"CRITICAL",IF(COUNTIFS(SM_Site,SelCrit,SM_Mat,$Q15,SM_Status,"REORDER")>0,"REORDER",IF(COUNTIFS(SM_Site,SelCrit,SM_Mat,$Q15,SM_Status,"OK")>0,"OK","NO USAGE"))))) -> NO DATA | N15: =COUNTIFS(SM_Site,SelCrit,SM_Mat,$Q15,SM_Status,"CRITICAL")+COUNTIFS(SM_Site,SelCrit,SM_Mat,$Q15,SM_Status,"OUT OF STOCK") -> 0 | O15: =SUMIFS(SM_Order,SM_Site,SelCrit,SM_Mat,$Q15) -> 0 | Q15: =INDEX(Mat_Code,2) -> SAND | R15: =INDEX(Mat_Lead,2) -> 2 | S15: =INDEX(Mat_Safety,2) -> 2 | T15: =R15+S15 -> 4 | U15: =R15 -> 2 | V15: =IF(ISNUMBER(H15),H15,0) -> 0 | W15: =IF(ISNUMBER(F15),F15,0) -> 0 | X15: =SUMPRODUCT(MIN(((($C$4=SM_Site)+($R$4="*"))>0)*(SM_Mat=$Q15)*SM_RBn+(1-((($C$4=SM_Site)+($R$4="*"))>0)*(SM_Mat=$Q15))*1000000000)) -> 1000000000 | Y15: =SUMPRODUCT(MIN(((($C$4=SM_Site)+($R$4="*"))>0)*(SM_Mat=$Q15)*SM_CRn+(1-((($C$4=SM_Site)+($R$4="*"))>0)*(SM_Mat=$Q15))*1000000000)) -> 1000000000 | Z15: =SUMPRODUCT(MIN(((($C$4=SM_Site)+($R$4="*"))>0)*(SM_Mat=$Q15)*SM_SOn+(1-((($C$4=SM_Site)+($R$4="*"))>0)*(SM_Mat=$Q15))*1000000000)) -> 1000000000 | AA15: =IF(AND(E15>0,D15>0),MIN(20,MAX(1,ROUND(D15/E15*20,0))),0) -> 0 | AB15: =IF(AND(E15>0,G15>0,R15>0),MIN(20,MAX(1,ROUND(G15*R15/E15*20,0))),0) -> 0 | AC15: =IF(AND(E15>0,G15>0,T15>0),MIN(20,MAX(1,ROUND(G15*T15/E15*20,0))),0) -> 0
B16: =INDEX(Mat_Short,3) -> Gravel 3/4" | C16: =INDEX(Mat_Unit,3) -> m3 | D16: =SUMIFS(SM_Stock,SM_Site,SelCrit,SM_Mat,$Q16) -> 0 | E16: =SUMIFS(SM_Cap,SM_Site,SelCrit,SM_Mat,$Q16) -> 0 | F16: =IF(E16>0,MAX(0,D16)/E16,"") | G16: =SUMIFS(SM_Rate,SM_Site,SelCrit,SM_Mat,$Q16) -> 0 | H16: =IF(G16>0,MAX(0,D16)/G16,"") | I16: =SUMIFS(SM_OnOrder,SM_Site,SelCrit,SM_Mat,$Q16) -> 0 | J16: =IF($X16>=1000000000,"",IF($X16<=AsOfDate,"NOW",$X16)) | K16: =IF($Y16>=1000000000,"",IF($Y16<=AsOfDate,"NOW",$Y16)) | L16: =IF($Z16>=1000000000,"",IF($Z16<=AsOfDate,"OUT",$Z16)) | M16: =IF(COUNTIFS(SM_Site,SelCrit,SM_Mat,$Q16)=0,"NO DATA",IF(COUNTIFS(SM_Site,SelCrit,SM_Mat,$Q16,SM_Status,"OUT OF STOCK")>0,"OUT OF STOCK",IF(COUNTIFS(SM_Site,SelCrit,SM_Mat,$Q16,SM_Status,"CRITICAL")>0,"CRITICAL",IF(COUNTIFS(SM_Site,SelCrit,SM_Mat,$Q16,SM_Status,"REORDER")>0,"REORDER",IF(COUNTIFS(SM_Site,SelCrit,SM_Mat,$Q16,SM_Status,"OK")>0,"OK","NO USAGE"))))) -> NO DATA | N16: =COUNTIFS(SM_Site,SelCrit,SM_Mat,$Q16,SM_Status,"CRITICAL")+COUNTIFS(SM_Site,SelCrit,SM_Mat,$Q16,SM_Status,"OUT OF STOCK") -> 0 | O16: =SUMIFS(SM_Order,SM_Site,SelCrit,SM_Mat,$Q16) -> 0 | Q16: =INDEX(Mat_Code,3) -> G34 | R16: =INDEX(Mat_Lead,3) -> 2 | S16: =INDEX(Mat_Safety,3) -> 2 | T16: =R16+S16 -> 4 | U16: =R16 -> 2 | V16: =IF(ISNUMBER(H16),H16,0) -> 0 | W16: =IF(ISNUMBER(F16),F16,0) -> 0 | X16: =SUMPRODUCT(MIN(((($C$4=SM_Site)+($R$4="*"))>0)*(SM_Mat=$Q16)*SM_RBn+(1-((($C$4=SM_Site)+($R$4="*"))>0)*(SM_Mat=$Q16))*1000000000)) -> 1000000000 | Y16: =SUMPRODUCT(MIN(((($C$4=SM_Site)+($R$4="*"))>0)*(SM_Mat=$Q16)*SM_CRn+(1-((($C$4=SM_Site)+($R$4="*"))>0)*(SM_Mat=$Q16))*1000000000)) -> 1000000000 | Z16: =SUMPRODUCT(MIN(((($C$4=SM_Site)+($R$4="*"))>0)*(SM_Mat=$Q16)*SM_SOn+(1-((($C$4=SM_Site)+($R$4="*"))>0)*(SM_Mat=$Q16))*1000000000)) -> 1000000000 | AA16: =IF(AND(E16>0,D16>0),MIN(20,MAX(1,ROUND(D16/E16*20,0))),0) -> 0 | AB16: =IF(AND(E16>0,G16>0,R16>0),MIN(20,MAX(1,ROUND(G16*R16/E16*20,0))),0) -> 0 | AC16: =IF(AND(E16>0,G16>0,T16>0),MIN(20,MAX(1,ROUND(G16*T16/E16*20,0))),0) -> 0
B17: =INDEX(Mat_Short,4) -> Gravel 3/8" | C17: =INDEX(Mat_Unit,4) -> m3 | D17: =SUMIFS(SM_Stock,SM_Site,SelCrit,SM_Mat,$Q17) -> 0 | E17: =SUMIFS(SM_Cap,SM_Site,SelCrit,SM_Mat,$Q17) -> 0 | F17: =IF(E17>0,MAX(0,D17)/E17,"") | G17: =SUMIFS(SM_Rate,SM_Site,SelCrit,SM_Mat,$Q17) -> 0 | H17: =IF(G17>0,MAX(0,D17)/G17,"") | I17: =SUMIFS(SM_OnOrder,SM_Site,SelCrit,SM_Mat,$Q17) -> 0 | J17: =IF($X17>=1000000000,"",IF($X17<=AsOfDate,"NOW",$X17)) | K17: =IF($Y17>=1000000000,"",IF($Y17<=AsOfDate,"NOW",$Y17)) | L17: =IF($Z17>=1000000000,"",IF($Z17<=AsOfDate,"OUT",$Z17)) | M17: =IF(COUNTIFS(SM_Site,SelCrit,SM_Mat,$Q17)=0,"NO DATA",IF(COUNTIFS(SM_Site,SelCrit,SM_Mat,$Q17,SM_Status,"OUT OF STOCK")>0,"OUT OF STOCK",IF(COUNTIFS(SM_Site,SelCrit,SM_Mat,$Q17,SM_Status,"CRITICAL")>0,"CRITICAL",IF(COUNTIFS(SM_Site,SelCrit,SM_Mat,$Q17,SM_Status,"REORDER")>0,"REORDER",IF(COUNTIFS(SM_Site,SelCrit,SM_Mat,$Q17,SM_Status,"OK")>0,"OK","NO USAGE"))))) -> NO DATA | N17: =COUNTIFS(SM_Site,SelCrit,SM_Mat,$Q17,SM_Status,"CRITICAL")+COUNTIFS(SM_Site,SelCrit,SM_Mat,$Q17,SM_Status,"OUT OF STOCK") -> 0 | O17: =SUMIFS(SM_Order,SM_Site,SelCrit,SM_Mat,$Q17) -> 0 | Q17: =INDEX(Mat_Code,4) -> G38 | R17: =INDEX(Mat_Lead,4) -> 2 | S17: =INDEX(Mat_Safety,4) -> 2 | T17: =R17+S17 -> 4 | U17: =R17 -> 2 | V17: =IF(ISNUMBER(H17),H17,0) -> 0 | W17: =IF(ISNUMBER(F17),F17,0) -> 0 | X17: =SUMPRODUCT(MIN(((($C$4=SM_Site)+($R$4="*"))>0)*(SM_Mat=$Q17)*SM_RBn+(1-((($C$4=SM_Site)+($R$4="*"))>0)*(SM_Mat=$Q17))*1000000000)) -> 1000000000 | Y17: =SUMPRODUCT(MIN(((($C$4=SM_Site)+($R$4="*"))>0)*(SM_Mat=$Q17)*SM_CRn+(1-((($C$4=SM_Site)+($R$4="*"))>0)*(SM_Mat=$Q17))*1000000000)) -> 1000000000 | Z17: =SUMPRODUCT(MIN(((($C$4=SM_Site)+($R$4="*"))>0)*(SM_Mat=$Q17)*SM_SOn+(1-((($C$4=SM_Site)+($R$4="*"))>0)*(SM_Mat=$Q17))*1000000000)) -> 1000000000 | AA17: =IF(AND(E17>0,D17>0),MIN(20,MAX(1,ROUND(D17/E17*20,0))),0) -> 0 | AB17: =IF(AND(E17>0,G17>0,R17>0),MIN(20,MAX(1,ROUND(G17*R17/E17*20,0))),0) -> 0 | AC17: =IF(AND(E17>0,G17>0,T17>0),MIN(20,MAX(1,ROUND(G17*T17/E17*20,0))),0) -> 0
B18: =INDEX(Mat_Short,5) -> Admixture | C18: =INDEX(Mat_Unit,5) -> L | D18: =SUMIFS(SM_Stock,SM_Site,SelCrit,SM_Mat,$Q18) -> 0 | E18: =SUMIFS(SM_Cap,SM_Site,SelCrit,SM_Mat,$Q18) -> 0 | F18: =IF(E18>0,MAX(0,D18)/E18,"") | G18: =SUMIFS(SM_Rate,SM_Site,SelCrit,SM_Mat,$Q18) -> 0 | H18: =IF(G18>0,MAX(0,D18)/G18,"") | I18: =SUMIFS(SM_OnOrder,SM_Site,SelCrit,SM_Mat,$Q18) -> 0 | J18: =IF($X18>=1000000000,"",IF($X18<=AsOfDate,"NOW",$X18)) | K18: =IF($Y18>=1000000000,"",IF($Y18<=AsOfDate,"NOW",$Y18)) | L18: =IF($Z18>=1000000000,"",IF($Z18<=AsOfDate,"OUT",$Z18)) | M18: =IF(COUNTIFS(SM_Site,SelCrit,SM_Mat,$Q18)=0,"NO DATA",IF(COUNTIFS(SM_Site,SelCrit,SM_Mat,$Q18,SM_Status,"OUT OF STOCK")>0,"OUT OF STOCK",IF(COUNTIFS(SM_Site,SelCrit,SM_Mat,$Q18,SM_Status,"CRITICAL")>0,"CRITICAL",IF(COUNTIFS(SM_Site,SelCrit,SM_Mat,$Q18,SM_Status,"REORDER")>0,"REORDER",IF(COUNTIFS(SM_Site,SelCrit,SM_Mat,$Q18,SM_Status,"OK")>0,"OK","NO USAGE"))))) -> NO DATA | N18: =COUNTIFS(SM_Site,SelCrit,SM_Mat,$Q18,SM_Status,"CRITICAL")+COUNTIFS(SM_Site,SelCrit,SM_Mat,$Q18,SM_Status,"OUT OF STOCK") -> 0 | O18: =SUMIFS(SM_Order,SM_Site,SelCrit,SM_Mat,$Q18) -> 0 | Q18: =INDEX(Mat_Code,5) -> ADM | R18: =INDEX(Mat_Lead,5) -> 5 | S18: =INDEX(Mat_Safety,5) -> 3 | T18: =R18+S18 -> 8 | U18: =R18 -> 5 | V18: =IF(ISNUMBER(H18),H18,0) -> 0 | W18: =IF(ISNUMBER(F18),F18,0) -> 0 | X18: =SUMPRODUCT(MIN(((($C$4=SM_Site)+($R$4="*"))>0)*(SM_Mat=$Q18)*SM_RBn+(1-((($C$4=SM_Site)+($R$4="*"))>0)*(SM_Mat=$Q18))*1000000000)) -> 1000000000 | Y18: =SUMPRODUCT(MIN(((($C$4=SM_Site)+($R$4="*"))>0)*(SM_Mat=$Q18)*SM_CRn+(1-((($C$4=SM_Site)+($R$4="*"))>0)*(SM_Mat=$Q18))*1000000000)) -> 1000000000 | Z18: =SUMPRODUCT(MIN(((($C$4=SM_Site)+($R$4="*"))>0)*(SM_Mat=$Q18)*SM_SOn+(1-((($C$4=SM_Site)+($R$4="*"))>0)*(SM_Mat=$Q18))*1000000000)) -> 1000000000 | AA18: =IF(AND(E18>0,D18>0),MIN(20,MAX(1,ROUND(D18/E18*20,0))),0) -> 0 | AB18: =IF(AND(E18>0,G18>0,R18>0),MIN(20,MAX(1,ROUND(G18*R18/E18*20,0))),0) -> 0 | AC18: =IF(AND(E18>0,G18>0,T18>0),MIN(20,MAX(1,ROUND(G18*T18/E18*20,0))),0) -> 0
B19: Days Remaining = stock on hand ÷ use per day (working days). Status, Reorder By and Critical On also count scheduled deliveries that arrive before the stock-out. All Sites: totals, the earliest date and the worst status across sites.
B20: ="STORAGE LEVELS — CEMENT SILO, AGGREGATE BINS & ADMIXTURE TANK ("&IF($R$4="*","all sites combined",$C$4)&") · fill = stock on hand ÷ max storage capacity" -> STORAGE LEVELS — CEMENT SILO, AGGREGATE BINS & ADMIXTURE TANK (all sites combined) · fill = stock on hand ÷ max storage capacity
F22: AGGREGATE BINS
B23: 100% — | C23: =IF(20=$AB$14,"– – critical level – –",IF(20=$AC$14,"– – reorder level – –",IF(20=$AA$14,TEXT($W$14,"0%"),""))) | F23: =IF(20=$AB$15,"– – critical level – –",IF(20=$AC$15,"– – reorder level – –",IF(20=$AA$15,TEXT($W$15,"0%"),""))) | H23: =IF(20=$AB$16,"– – critical level – –",IF(20=$AC$16,"– – reorder level – –",IF(20=$AA$16,TEXT($W$16,"0%"),""))) | J23: =IF(20=$AB$17,"– – critical level – –",IF(20=$AC$17,"– – reorder level – –",IF(20=$AA$17,TEXT($W$17,"0%"),""))) | M23: =IF(20=$AB$18,"– – critical level – –",IF(20=$AC$18,"– – reorder level – –",IF(20=$AA$18,TEXT($W$18,"0%"),"")))
C24: =IF(19=$AB$14,"– – critical level – –",IF(19=$AC$14,"– – reorder level – –",IF(19=$AA$14,TEXT($W$14,"0%"),""))) | F24: =IF(19=$AB$15,"– – critical level – –",IF(19=$AC$15,"– – reorder level – –",IF(19=$AA$15,TEXT($W$15,"0%"),""))) | H24: =IF(19=$AB$16,"– – critical level – –",IF(19=$AC$16,"– – reorder level – –",IF(19=$AA$16,TEXT($W$16,"0%"),""))) | J24: =IF(19=$AB$17,"– – critical level – –",IF(19=$AC$17,"– – reorder level – –",IF(19=$AA$17,TEXT($W$17,"0%"),""))) | M24: =IF(19=$AB$18,"– – critical level – –",IF(19=$AC$18,"– – reorder level – –",IF(19=$AA$18,TEXT($W$18,"0%"),"")))
C25: =IF(18=$AB$14,"– – critical level – –",IF(18=$AC$14,"– – reorder level – –",IF(18=$AA$14,TEXT($W$14,"0%"),""))) | F25: =IF(18=$AB$15,"– – critical level – –",IF(18=$AC$15,"– – reorder level – –",IF(18=$AA$15,TEXT($W$15,"0%"),""))) | H25: =IF(18=$AB$16,"– – critical level – –",IF(18=$AC$16,"– – reorder level – –",IF(18=$AA$16,TEXT($W$16,"0%"),""))) | J25: =IF(18=$AB$17,"– – critical level – –",IF(18=$AC$17,"– – reorder level – –",IF(18=$AA$17,TEXT($W$17,"0%"),""))) | M25: =IF(18=$AB$18,"– – critical level – –",IF(18=$AC$18,"– – reorder level – –",IF(18=$AA$18,TEXT($W$18,"0%"),"")))
C26: =IF(17=$AB$14,"– – critical level – –",IF(17=$AC$14,"– – reorder level – –",IF(17=$AA$14,TEXT($W$14,"0%"),""))) | F26: =IF(17=$AB$15,"– – critical level – –",IF(17=$AC$15,"– – reorder level – –",IF(17=$AA$15,TEXT($W$15,"0%"),""))) | H26: =IF(17=$AB$16,"– – critical level – –",IF(17=$AC$16,"– – reorder level – –",IF(17=$AA$16,TEXT($W$16,"0%"),""))) | J26: =IF(17=$AB$17,"– – critical level – –",IF(17=$AC$17,"– – reorder level – –",IF(17=$AA$17,TEXT($W$17,"0%"),""))) | M26: =IF(17=$AB$18,"– – critical level – –",IF(17=$AC$18,"– – reorder level – –",IF(17=$AA$18,TEXT($W$18,"0%"),"")))
C27: =IF(16=$AB$14,"– – critical level – –",IF(16=$AC$14,"– – reorder level – –",IF(16=$AA$14,TEXT($W$14,"0%"),""))) | F27: =IF(16=$AB$15,"– – critical level – –",IF(16=$AC$15,"– – reorder level – –",IF(16=$AA$15,TEXT($W$15,"0%"),""))) | H27: =IF(16=$AB$16,"– – critical level – –",IF(16=$AC$16,"– – reorder level – –",IF(16=$AA$16,TEXT($W$16,"0%"),""))) | J27: =IF(16=$AB$17,"– – critical level – –",IF(16=$AC$17,"– – reorder level – –",IF(16=$AA$17,TEXT($W$17,"0%"),""))) | M27: =IF(16=$AB$18,"– – critical level – –",IF(16=$AC$18,"– – reorder level – –",IF(16=$AA$18,TEXT($W$18,"0%"),"")))
B28: 75% — | C28: =IF(15=$AB$14,"– – critical level – –",IF(15=$AC$14,"– – reorder level – –",IF(15=$AA$14,TEXT($W$14,"0%"),""))) | F28: =IF(15=$AB$15,"– – critical level – –",IF(15=$AC$15,"– – reorder level – –",IF(15=$AA$15,TEXT($W$15,"0%"),""))) | H28: =IF(15=$AB$16,"– – critical level – –",IF(15=$AC$16,"– – reorder level – –",IF(15=$AA$16,TEXT($W$16,"0%"),""))) | J28: =IF(15=$AB$17,"– – critical level – –",IF(15=$AC$17,"– – reorder level – –",IF(15=$AA$17,TEXT($W$17,"0%"),""))) | M28: =IF(15=$AB$18,"– – critical level – –",IF(15=$AC$18,"– – reorder level – –",IF(15=$AA$18,TEXT($W$18,"0%"),"")))
C29: =IF(14=$AB$14,"– – critical level – –",IF(14=$AC$14,"– – reorder level – –",IF(14=$AA$14,TEXT($W$14,"0%"),""))) | F29: =IF(14=$AB$15,"– – critical level – –",IF(14=$AC$15,"– – reorder level – –",IF(14=$AA$15,TEXT($W$15,"0%"),""))) | H29: =IF(14=$AB$16,"– – critical level – –",IF(14=$AC$16,"– – reorder level – –",IF(14=$AA$16,TEXT($W$16,"0%"),""))) | J29: =IF(14=$AB$17,"– – critical level – –",IF(14=$AC$17,"– – reorder level – –",IF(14=$AA$17,TEXT($W$17,"0%"),""))) | M29: =IF(14=$AB$18,"– – critical level – –",IF(14=$AC$18,"– – reorder level – –",IF(14=$AA$18,TEXT($W$18,"0%"),"")))
C30: =IF(13=$AB$14,"– – critical level – –",IF(13=$AC$14,"– – reorder level – –",IF(13=$AA$14,TEXT($W$14,"0%"),""))) | F30: =IF(13=$AB$15,"– – critical level – –",IF(13=$AC$15,"– – reorder level – –",IF(13=$AA$15,TEXT($W$15,"0%"),""))) | H30: =IF(13=$AB$16,"– – critical level – –",IF(13=$AC$16,"– – reorder level – –",IF(13=$AA$16,TEXT($W$16,"0%"),""))) | J30: =IF(13=$AB$17,"– – critical level – –",IF(13=$AC$17,"– – reorder level – –",IF(13=$AA$17,TEXT($W$17,"0%"),""))) | M30: =IF(13=$AB$18,"– – critical level – –",IF(13=$AC$18,"– – reorder level – –",IF(13=$AA$18,TEXT($W$18,"0%"),"")))
C31: =IF(12=$AB$14,"– – critical level – –",IF(12=$AC$14,"– – reorder level – –",IF(12=$AA$14,TEXT($W$14,"0%"),""))) | F31: =IF(12=$AB$15,"– – critical level – –",IF(12=$AC$15,"– – reorder level – –",IF(12=$AA$15,TEXT($W$15,"0%"),""))) | H31: =IF(12=$AB$16,"– – critical level – –",IF(12=$AC$16,"– – reorder level – –",IF(12=$AA$16,TEXT($W$16,"0%"),""))) | J31: =IF(12=$AB$17,"– – critical level – –",IF(12=$AC$17,"– – reorder level – –",IF(12=$AA$17,TEXT($W$17,"0%"),""))) | M31: =IF(12=$AB$18,"– – critical level – –",IF(12=$AC$18,"– – reorder level – –",IF(12=$AA$18,TEXT($W$18,"0%"),"")))
C32: =IF(11=$AB$14,"– – critical level – –",IF(11=$AC$14,"– – reorder level – –",IF(11=$AA$14,TEXT($W$14,"0%"),""))) | F32: =IF(11=$AB$15,"– – critical level – –",IF(11=$AC$15,"– – reorder level – –",IF(11=$AA$15,TEXT($W$15,"0%"),""))) | H32: =IF(11=$AB$16,"– – critical level – –",IF(11=$AC$16,"– – reorder level – –",IF(11=$AA$16,TEXT($W$16,"0%"),""))) | J32: =IF(11=$AB$17,"– – critical level – –",IF(11=$AC$17,"– – reorder level – –",IF(11=$AA$17,TEXT($W$17,"0%"),""))) | M32: =IF(11=$AB$18,"– – critical level – –",IF(11=$AC$18,"– – reorder level – –",IF(11=$AA$18,TEXT($W$18,"0%"),"")))
B33: 50% — | C33: =IF(10=$AB$14,"– – critical level – –",IF(10=$AC$14,"– – reorder level – –",IF(10=$AA$14,TEXT($W$14,"0%"),""))) | F33: =IF(10=$AB$15,"– – critical level – –",IF(10=$AC$15,"– – reorder level – –",IF(10=$AA$15,TEXT($W$15,"0%"),""))) | H33: =IF(10=$AB$16,"– – critical level – –",IF(10=$AC$16,"– – reorder level – –",IF(10=$AA$16,TEXT($W$16,"0%"),""))) | J33: =IF(10=$AB$17,"– – critical level – –",IF(10=$AC$17,"– – reorder level – –",IF(10=$AA$17,TEXT($W$17,"0%"),""))) | M33: =IF(10=$AB$18,"– – critical level – –",IF(10=$AC$18,"– – reorder level – –",IF(10=$AA$18,TEXT($W$18,"0%"),"")))
C34: =IF(9=$AB$14,"– – critical level – –",IF(9=$AC$14,"– – reorder level – –",IF(9=$AA$14,TEXT($W$14,"0%"),""))) | F34: =IF(9=$AB$15,"– – critical level – –",IF(9=$AC$15,"– – reorder level – –",IF(9=$AA$15,TEXT($W$15,"0%"),""))) | H34: =IF(9=$AB$16,"– – critical level – –",IF(9=$AC$16,"– – reorder level – –",IF(9=$AA$16,TEXT($W$16,"0%"),""))) | J34: =IF(9=$AB$17,"– – critical level – –",IF(9=$AC$17,"– – reorder level – –",IF(9=$AA$17,TEXT($W$17,"0%"),""))) | M34: =IF(9=$AB$18,"– – critical level – –",IF(9=$AC$18,"– – reorder level – –",IF(9=$AA$18,TEXT($W$18,"0%"),"")))
C35: =IF(8=$AB$14,"– – critical level – –",IF(8=$AC$14,"– – reorder level – –",IF(8=$AA$14,TEXT($W$14,"0%"),""))) | F35: =IF(8=$AB$15,"– – critical level – –",IF(8=$AC$15,"– – reorder level – –",IF(8=$AA$15,TEXT($W$15,"0%"),""))) | H35: =IF(8=$AB$16,"– – critical level – –",IF(8=$AC$16,"– – reorder level – –",IF(8=$AA$16,TEXT($W$16,"0%"),""))) | J35: =IF(8=$AB$17,"– – critical level – –",IF(8=$AC$17,"– – reorder level – –",IF(8=$AA$17,TEXT($W$17,"0%"),""))) | M35: =IF(8=$AB$18,"– – critical level – –",IF(8=$AC$18,"– – reorder level – –",IF(8=$AA$18,TEXT($W$18,"0%"),"")))
C36: =IF(7=$AB$14,"– – critical level – –",IF(7=$AC$14,"– – reorder level – –",IF(7=$AA$14,TEXT($W$14,"0%"),""))) | F36: =IF(7=$AB$15,"– – critical level – –",IF(7=$AC$15,"– – reorder level – –",IF(7=$AA$15,TEXT($W$15,"0%"),""))) | H36: =IF(7=$AB$16,"– – critical level – –",IF(7=$AC$16,"– – reorder level – –",IF(7=$AA$16,TEXT($W$16,"0%"),""))) | J36: =IF(7=$AB$17,"– – critical level – –",IF(7=$AC$17,"– – reorder level – –",IF(7=$AA$17,TEXT($W$17,"0%"),""))) | M36: =IF(7=$AB$18,"– – critical level – –",IF(7=$AC$18,"– – reorder level – –",IF(7=$AA$18,TEXT($W$18,"0%"),"")))
C37: =IF(6=$AB$14,"– – critical level – –",IF(6=$AC$14,"– – reorder level – –",IF(6=$AA$14,TEXT($W$14,"0%"),""))) | F37: =IF(6=$AB$15,"– – critical level – –",IF(6=$AC$15,"– – reorder level – –",IF(6=$AA$15,TEXT($W$15,"0%"),""))) | H37: =IF(6=$AB$16,"– – critical level – –",IF(6=$AC$16,"– – reorder level – –",IF(6=$AA$16,TEXT($W$16,"0%"),""))) | J37: =IF(6=$AB$17,"– – critical level – –",IF(6=$AC$17,"– – reorder level – –",IF(6=$AA$17,TEXT($W$17,"0%"),""))) | M37: =IF(6=$AB$18,"– – critical level – –",IF(6=$AC$18,"– – reorder level – –",IF(6=$AA$18,TEXT($W$18,"0%"),"")))
B38: 25% — | C38: =IF(5=$AB$14,"– – critical level – –",IF(5=$AC$14,"– – reorder level – –",IF(5=$AA$14,TEXT($W$14,"0%"),""))) | F38: =IF(5=$AB$15,"– – critical level – –",IF(5=$AC$15,"– – reorder level – –",IF(5=$AA$15,TEXT($W$15,"0%"),""))) | H38: =IF(5=$AB$16,"– – critical level – –",IF(5=$AC$16,"– – reorder level – –",IF(5=$AA$16,TEXT($W$16,"0%"),""))) | J38: =IF(5=$AB$17,"– – critical level – –",IF(5=$AC$17,"– – reorder level – –",IF(5=$AA$17,TEXT($W$17,"0%"),""))) | M38: =IF(5=$AB$18,"– – critical level – –",IF(5=$AC$18,"– – reorder level – –",IF(5=$AA$18,TEXT($W$18,"0%"),"")))
C39: =IF(4=$AB$14,"– – critical level – –",IF(4=$AC$14,"– – reorder level – –",IF(4=$AA$14,TEXT($W$14,"0%"),""))) | F39: =IF(4=$AB$15,"– – critical level – –",IF(4=$AC$15,"– – reorder level – –",IF(4=$AA$15,TEXT($W$15,"0%"),""))) | H39: =IF(4=$AB$16,"– – critical level – –",IF(4=$AC$16,"– – reorder level – –",IF(4=$AA$16,TEXT($W$16,"0%"),""))) | J39: =IF(4=$AB$17,"– – critical level – –",IF(4=$AC$17,"– – reorder level – –",IF(4=$AA$17,TEXT($W$17,"0%"),""))) | M39: =IF(4=$AB$18,"– – critical level – –",IF(4=$AC$18,"– – reorder level – –",IF(4=$AA$18,TEXT($W$18,"0%"),"")))
C40: =IF(3=$AB$14,"– – critical level – –",IF(3=$AC$14,"– – reorder level – –",IF(3=$AA$14,TEXT($W$14,"0%"),""))) | F40: =IF(3=$AB$15,"– – critical level – –",IF(3=$AC$15,"– – reorder level – –",IF(3=$AA$15,TEXT($W$15,"0%"),""))) | H40: =IF(3=$AB$16,"– – critical level – –",IF(3=$AC$16,"– – reorder level – –",IF(3=$AA$16,TEXT($W$16,"0%"),""))) | J40: =IF(3=$AB$17,"– – critical level – –",IF(3=$AC$17,"– – reorder level – –",IF(3=$AA$17,TEXT($W$17,"0%"),""))) | M40: =IF(3=$AB$18,"– – critical level – –",IF(3=$AC$18,"– – reorder level – –",IF(3=$AA$18,TEXT($W$18,"0%"),"")))
C41: =IF(2=$AB$14,"– – critical level – –",IF(2=$AC$14,"– – reorder level – –",IF(2=$AA$14,TEXT($W$14,"0%"),""))) | F41: =IF(2=$AB$15,"– – critical level – –",IF(2=$AC$15,"– – reorder level – –",IF(2=$AA$15,TEXT($W$15,"0%"),""))) | H41: =IF(2=$AB$16,"– – critical level – –",IF(2=$AC$16,"– – reorder level – –",IF(2=$AA$16,TEXT($W$16,"0%"),""))) | J41: =IF(2=$AB$17,"– – critical level – –",IF(2=$AC$17,"– – reorder level – –",IF(2=$AA$17,TEXT($W$17,"0%"),""))) | M41: =IF(2=$AB$18,"– – critical level – –",IF(2=$AC$18,"– – reorder level – –",IF(2=$AA$18,TEXT($W$18,"0%"),"")))
B42: 0% — | C42: =IF(1=$AB$14,"– – critical level – –",IF(1=$AC$14,"– – reorder level – –",IF(1=$AA$14,TEXT($W$14,"0%"),""))) | F42: =IF(1=$AB$15,"– – critical level – –",IF(1=$AC$15,"– – reorder level – –",IF(1=$AA$15,TEXT($W$15,"0%"),""))) | H42: =IF(1=$AB$16,"– – critical level – –",IF(1=$AC$16,"– – reorder level – –",IF(1=$AA$16,TEXT($W$16,"0%"),""))) | J42: =IF(1=$AB$17,"– – critical level – –",IF(1=$AC$17,"– – reorder level – –",IF(1=$AA$17,TEXT($W$17,"0%"),""))) | M42: =IF(1=$AB$18,"– – critical level – –",IF(1=$AC$18,"– – reorder level – –",IF(1=$AA$18,TEXT($W$18,"0%"),"")))
C46: =UPPER(INDEX(Mat_Short,1))&" SILO" -> CEMENT SILO | F46: =UPPER(INDEX(Mat_Short,2))&" BIN" -> SAND BIN | H46: =UPPER(INDEX(Mat_Short,3))&" BIN" -> GRAVEL 3/4" BIN | J46: =UPPER(INDEX(Mat_Short,4))&" BIN" -> GRAVEL 3/8" BIN | M46: =UPPER(INDEX(Mat_Short,5))&" TANK" -> ADMIXTURE TANK
C47: =IF(ISNUMBER(F14),TEXT(F14,"0%")&" full",IF(M14="NO DATA","not set up","no capacity set")) -> not set up | F47: =IF(ISNUMBER(F15),TEXT(F15,"0%")&" full",IF(M15="NO DATA","not set up","no capacity set")) -> not set up | H47: =IF(ISNUMBER(F16),TEXT(F16,"0%")&" full",IF(M16="NO DATA","not set up","no capacity set")) -> not set up | J47: =IF(ISNUMBER(F17),TEXT(F17,"0%")&" full",IF(M17="NO DATA","not set up","no capacity set")) -> not set up | M47: =IF(ISNUMBER(F18),TEXT(F18,"0%")&" full",IF(M18="NO DATA","not set up","no capacity set")) -> not set up
...

Sheet Current Inventory
A1: 1 · Current Inventory — Stock on Hand per Site
A2: One row per site and material: physical count (beginning balance), count date and storage capacity. Deliveries and consumption from the count date up to the As-of Date are applied automatically.
A3: ="Stock as of "&TEXT(AsOfDate,"dd mmm yyyy")&" (As-of Date is set in Settings)" -> Stock as of 31 Oct 2026 (As-of Date is set in Settings)
A4: Site / Project | B4: Material Code | C4: Material | D4: Unit | E4: Count Date | F4: Beginning Balance (physical count) | G4: Max Storage Capacity | H4: Deliveries Received (+) | I4: Consumption (−) | J4: Current Stock | K4: % of Capacity | L4: Check | M4: Remarks
A5: Example Site | B5: CEM | C5: Cement | D5: bags | E5: 46296 | F5: 1500 | G5: 3000 | H5: (auto) | I5: (auto) | J5: (auto) | K5: (auto) | M5: Example row — shows the format, not counted
A6: Batulao Parkhomes | B6: CEM | C6: =IF($B6="","",IFERROR(INDEX(Mat_Short,MATCH($B6,Mat_Code,0)),"⚠ Unknown code")) -> Cement | D6: =IF($B6="","",IFERROR(INDEX(Mat_Unit,MATCH($B6,Mat_Code,0)),"")) -> bags | H6: =IF(OR($A6="",$B6=""),"",SUMIFS(Del_Qty,Del_Site,$A6,Del_Mat,$B6,Del_Status,"Received",Del_Date,">="&N($E6),Del_Date,"<="&AsOfDate)) -> 0 | I6: =IF(OR($A6="",$B6=""),"",IFERROR(SUMIFS(INDEX(Con_Use,0,MATCH($B6,Mat_Code,0)),Con_Site,$A6,Con_Date,">="&N($E6),Con_Date,"<="&AsOfDate),0)) -> 0 | J6: =IF(OR($A6="",$B6="",$F6=""),"",$F6+$H6-$I6) | K6: =IF(OR($J6="",N($G6)<=0),"",MAX(0,$J6)/$G6) | L6: =IF(OR($A6="",$B6=""),"",IF(COUNTIFS(CI_Site,$A6,CI_Mat,$B6)>1,"⚠ Duplicate site + material row",IF(ISNA(MATCH($B6,Mat_Code,0)),"⚠ Unknown material code",IF($E6="","⚠ Enter count date",IF($F6="","⚠ Enter beginning balance",IF(N($G6)<=0,"⚠ Enter storage capacity",IF($E6>AsOfDate,"⚠ Count date is after the As-of Date",IF($J6<0,"⚠ Negative stock – check logs or recount","OK")))))))) -> ⚠ Enter count date
A7: Batulao Parkhomes | B7: SAND | C7: =IF($B7="","",IFERROR(INDEX(Mat_Short,MATCH($B7,Mat_Code,0)),"⚠ Unknown code")) -> Sand | D7: =IF($B7="","",IFERROR(INDEX(Mat_Unit,MATCH($B7,Mat_Code,0)),"")) -> m3 | H7: =IF(OR($A7="",$B7=""),"",SUMIFS(Del_Qty,Del_Site,$A7,Del_Mat,$B7,Del_Status,"Received",Del_Date,">="&N($E7),Del_Date,"<="&AsOfDate)) -> 0 | I7: =IF(OR($A7="",$B7=""),"",IFERROR(SUMIFS(INDEX(Con_Use,0,MATCH($B7,Mat_Code,0)),Con_Site,$A7,Con_Date,">="&N($E7),Con_Date,"<="&AsOfDate),0)) -> 0 | J7: =IF(OR($A7="",$B7="",$F7=""),"",$F7+$H7-$I7) | K7: =IF(OR($J7="",N($G7)<=0),"",MAX(0,$J7)/$G7) | L7: =IF(OR($A7="",$B7=""),"",IF(COUNTIFS(CI_Site,$A7,CI_Mat,$B7)>1,"⚠ Duplicate site + material row",IF(ISNA(MATCH($B7,Mat_Code,0)),"⚠ Unknown material code",IF($E7="","⚠ Enter count date",IF($F7="","⚠ Enter beginning balance",IF(N($G7)<=0,"⚠ Enter storage capacity",IF($E7>AsOfDate,"⚠ Count date is after the As-of Date",IF($J7<0,"⚠ Negative stock – check logs or recount","OK")))))))) -> ⚠ Enter count date
A8: Batulao Parkhomes | B8: G34 | C8: =IF($B8="","",IFERROR(INDEX(Mat_Short,MATCH($B8,Mat_Code,0)),"⚠ Unknown code")) -> Gravel 3/4" | D8: =IF($B8="","",IFERROR(INDEX(Mat_Unit,MATCH($B8,Mat_Code,0)),"")) -> m3 | H8: =IF(OR($A8="",$B8=""),"",SUMIFS(Del_Qty,Del_Site,$A8,Del_Mat,$B8,Del_Status,"Received",Del_Date,">="&N($E8),Del_Date,"<="&AsOfDate)) -> 0 | I8: =IF(OR($A8="",$B8=""),"",IFERROR(SUMIFS(INDEX(Con_Use,0,MATCH($B8,Mat_Code,0)),Con_Site,$A8,Con_Date,">="&N($E8),Con_Date,"<="&AsOfDate),0)) -> 0 | J8: =IF(OR($A8="",$B8="",$F8=""),"",$F8+$H8-$I8) | K8: =IF(OR($J8="",N($G8)<=0),"",MAX(0,$J8)/$G8) | L8: =IF(OR($A8="",$B8=""),"",IF(COUNTIFS(CI_Site,$A8,CI_Mat,$B8)>1,"⚠ Duplicate site + material row",IF(ISNA(MATCH($B8,Mat_Code,0)),"⚠ Unknown material code",IF($E8="","⚠ Enter count date",IF($F8="","⚠ Enter beginning balance",IF(N($G8)<=0,"⚠ Enter storage capacity",IF($E8>AsOfDate,"⚠ Count date is after the As-of Date",IF($J8<0,"⚠ Negative stock – check logs or recount","OK")))))))) -> ⚠ Enter count date
A9: Batulao Parkhomes | B9: G38 | C9: =IF($B9="","",IFERROR(INDEX(Mat_Short,MATCH($B9,Mat_Code,0)),"⚠ Unknown code")) -> Gravel 3/8" | D9: =IF($B9="","",IFERROR(INDEX(Mat_Unit,MATCH($B9,Mat_Code,0)),"")) -> m3 | H9: =IF(OR($A9="",$B9=""),"",SUMIFS(Del_Qty,Del_Site,$A9,Del_Mat,$B9,Del_Status,"Received",Del_Date,">="&N($E9),Del_Date,"<="&AsOfDate)) -> 0 | I9: =IF(OR($A9="",$B9=""),"",IFERROR(SUMIFS(INDEX(Con_Use,0,MATCH($B9,Mat_Code,0)),Con_Site,$A9,Con_Date,">="&N($E9),Con_Date,"<="&AsOfDate),0)) -> 0 | J9: =IF(OR($A9="",$B9="",$F9=""),"",$F9+$H9-$I9) | K9: =IF(OR($J9="",N($G9)<=0),"",MAX(0,$J9)/$G9) | L9: =IF(OR($A9="",$B9=""),"",IF(COUNTIFS(CI_Site,$A9,CI_Mat,$B9)>1,"⚠ Duplicate site + material row",IF(ISNA(MATCH($B9,Mat_Code,0)),"⚠ Unknown material code",IF($E9="","⚠ Enter count date",IF($F9="","⚠ Enter beginning balance",IF(N($G9)<=0,"⚠ Enter storage capacity",IF($E9>AsOfDate,"⚠ Count date is after the As-of Date",IF($J9<0,"⚠ Negative stock – check logs or recount","OK")))))))) -> ⚠ Enter count date
A10: Batulao Parkhomes | B10: ADM | C10: =IF($B10="","",IFERROR(INDEX(Mat_Short,MATCH($B10,Mat_Code,0)),"⚠ Unknown code")) -> Admixture | D10: =IF($B10="","",IFERROR(INDEX(Mat_Unit,MATCH($B10,Mat_Code,0)),"")) -> L | H10: =IF(OR($A10="",$B10=""),"",SUMIFS(Del_Qty,Del_Site,$A10,Del_Mat,$B10,Del_Status,"Received",Del_Date,">="&N($E10),Del_Date,"<="&AsOfDate)) -> 0 | I10: =IF(OR($A10="",$B10=""),"",IFERROR(SUMIFS(INDEX(Con_Use,0,MATCH($B10,Mat_Code,0)),Con_Site,$A10,Con_Date,">="&N($E10),Con_Date,"<="&AsOfDate),0)) -> 0 | J10: =IF(OR($A10="",$B10="",$F10=""),"",$F10+$H10-$I10) | K10: =IF(OR($J10="",N($G10)<=0),"",MAX(0,$J10)/$G10) | L10: =IF(OR($A10="",$B10=""),"",IF(COUNTIFS(CI_Site,$A10,CI_Mat,$B10)>1,"⚠ Duplicate site + material row",IF(ISNA(MATCH($B10,Mat_Code,0)),"⚠ Unknown material code",IF($E10="","⚠ Enter count date",IF($F10="","⚠ Enter beginning balance",IF(N($G10)<=0,"⚠ Enter storage capacity",IF($E10>AsOfDate,"⚠ Count date is after the As-of Date",IF($J10<0,"⚠ Negative stock – check logs or recount","OK")))))))) -> ⚠ Enter count date
A11: Calauan (Alora+Amani) | B11: CEM | C11: =IF($B11="","",IFERROR(INDEX(Mat_Short,MATCH($B11,Mat_Code,0)),"⚠ Unknown code")) -> Cement | D11: =IF($B11="","",IFERROR(INDEX(Mat_Unit,MATCH($B11,Mat_Code,0)),"")) -> bags | H11: =IF(OR($A11="",$B11=""),"",SUMIFS(Del_Qty,Del_Site,$A11,Del_Mat,$B11,Del_Status,"Received",Del_Date,">="&N($E11),Del_Date,"<="&AsOfDate)) -> 0 | I11: =IF(OR($A11="",$B11=""),"",IFERROR(SUMIFS(INDEX(Con_Use,0,MATCH($B11,Mat_Code,0)),Con_Site,$A11,Con_Date,">="&N($E11),Con_Date,"<="&AsOfDate),0)) -> 0 | J11: =IF(OR($A11="",$B11="",$F11=""),"",$F11+$H11-$I11) | K11: =IF(OR($J11="",N($G11)<=0),"",MAX(0,$J11)/$G11) | L11: =IF(OR($A11="",$B11=""),"",IF(COUNTIFS(CI_Site,$A11,CI_Mat,$B11)>1,"⚠ Duplicate site + material row",IF(ISNA(MATCH($B11,Mat_Code,0)),"⚠ Unknown material code",IF($E11="","⚠ Enter count date",IF($F11="","⚠ Enter beginning balance",IF(N($G11)<=0,"⚠ Enter storage capacity",IF($E11>AsOfDate,"⚠ Count date is after the As-of Date",IF($J11<0,"⚠ Negative stock – check logs or recount","OK")))))))) -> ⚠ Enter count date
A12: Calauan (Alora+Amani) | B12: SAND | C12: =IF($B12="","",IFERROR(INDEX(Mat_Short,MATCH($B12,Mat_Code,0)),"⚠ Unknown code")) -> Sand | D12: =IF($B12="","",IFERROR(INDEX(Mat_Unit,MATCH($B12,Mat_Code,0)),"")) -> m3 | H12: =IF(OR($A12="",$B12=""),"",SUMIFS(Del_Qty,Del_Site,$A12,Del_Mat,$B12,Del_Status,"Received",Del_Date,">="&N($E12),Del_Date,"<="&AsOfDate)) -> 0 | I12: =IF(OR($A12="",$B12=""),"",IFERROR(SUMIFS(INDEX(Con_Use,0,MATCH($B12,Mat_Code,0)),Con_Site,$A12,Con_Date,">="&N($E12),Con_Date,"<="&AsOfDate),0)) -> 0 | J12: =IF(OR($A12="",$B12="",$F12=""),"",$F12+$H12-$I12) | K12: =IF(OR($J12="",N($G12)<=0),"",MAX(0,$J12)/$G12) | L12: =IF(OR($A12="",$B12=""),"",IF(COUNTIFS(CI_Site,$A12,CI_Mat,$B12)>1,"⚠ Duplicate site + material row",IF(ISNA(MATCH($B12,Mat_Code,0)),"⚠ Unknown material code",IF($E12="","⚠ Enter count date",IF($F12="","⚠ Enter beginning balance",IF(N($G12)<=0,"⚠ Enter storage capacity",IF($E12>AsOfDate,"⚠ Count date is after the As-of Date",IF($J12<0,"⚠ Negative stock – check logs or recount","OK")))))))) -> ⚠ Enter count date
A13: Calauan (Alora+Amani) | B13: G34 | C13: =IF($B13="","",IFERROR(INDEX(Mat_Short,MATCH($B13,Mat_Code,0)),"⚠ Unknown code")) -> Gravel 3/4" | D13: =IF($B13="","",IFERROR(INDEX(Mat_Unit,MATCH($B13,Mat_Code,0)),"")) -> m3 | H13: =IF(OR($A13="",$B13=""),"",SUMIFS(Del_Qty,Del_Site,$A13,Del_Mat,$B13,Del_Status,"Received",Del_Date,">="&N($E13),Del_Date,"<="&AsOfDate)) -> 0 | I13: =IF(OR($A13="",$B13=""),"",IFERROR(SUMIFS(INDEX(Con_Use,0,MATCH($B13,Mat_Code,0)),Con_Site,$A13,Con_Date,">="&N($E13),Con_Date,"<="&AsOfDate),0)) -> 0 | J13: =IF(OR($A13="",$B13="",$F13=""),"",$F13+$H13-$I13) | K13: =IF(OR($J13="",N($G13)<=0),"",MAX(0,$J13)/$G13) | L13: =IF(OR($A13="",$B13=""),"",IF(COUNTIFS(CI_Site,$A13,CI_Mat,$B13)>1,"⚠ Duplicate site + material row",IF(ISNA(MATCH($B13,Mat_Code,0)),"⚠ Unknown material code",IF($E13="","⚠ Enter count date",IF($F13="","⚠ Enter beginning balance",IF(N($G13)<=0,"⚠ Enter storage capacity",IF($E13>AsOfDate,"⚠ Count date is after the As-of Date",IF($J13<0,"⚠ Negative stock – check logs or recount","OK")))))))) -> ⚠ Enter count date
A14: Calauan (Alora+Amani) | B14: G38 | C14: =IF($B14="","",IFERROR(INDEX(Mat_Short,MATCH($B14,Mat_Code,0)),"⚠ Unknown code")) -> Gravel 3/8" | D14: =IF($B14="","",IFERROR(INDEX(Mat_Unit,MATCH($B14,Mat_Code,0)),"")) -> m3 | H14: =IF(OR($A14="",$B14=""),"",SUMIFS(Del_Qty,Del_Site,$A14,Del_Mat,$B14,Del_Status,"Received",Del_Date,">="&N($E14),Del_Date,"<="&AsOfDate)) -> 0 | I14: =IF(OR($A14="",$B14=""),"",IFERROR(SUMIFS(INDEX(Con_Use,0,MATCH($B14,Mat_Code,0)),Con_Site,$A14,Con_Date,">="&N($E14),Con_Date,"<="&AsOfDate),0)) -> 0 | J14: =IF(OR($A14="",$B14="",$F14=""),"",$F14+$H14-$I14) | K14: =IF(OR($J14="",N($G14)<=0),"",MAX(0,$J14)/$G14) | L14: =IF(OR($A14="",$B14=""),"",IF(COUNTIFS(CI_Site,$A14,CI_Mat,$B14)>1,"⚠ Duplicate site + material row",IF(ISNA(MATCH($B14,Mat_Code,0)),"⚠ Unknown material code",IF($E14="","⚠ Enter count date",IF($F14="","⚠ Enter beginning balance",IF(N($G14)<=0,"⚠ Enter storage capacity",IF($E14>AsOfDate,"⚠ Count date is after the As-of Date",IF($J14<0,"⚠ Negative stock – check logs or recount","OK")))))))) -> ⚠ Enter count date
A15: Calauan (Alora+Amani) | B15: ADM | C15: =IF($B15="","",IFERROR(INDEX(Mat_Short,MATCH($B15,Mat_Code,0)),"⚠ Unknown code")) -> Admixture | D15: =IF($B15="","",IFERROR(INDEX(Mat_Unit,MATCH($B15,Mat_Code,0)),"")) -> L | H15: =IF(OR($A15="",$B15=""),"",SUMIFS(Del_Qty,Del_Site,$A15,Del_Mat,$B15,Del_Status,"Received",Del_Date,">="&N($E15),Del_Date,"<="&AsOfDate)) -> 0 | I15: =IF(OR($A15="",$B15=""),"",IFERROR(SUMIFS(INDEX(Con_Use,0,MATCH($B15,Mat_Code,0)),Con_Site,$A15,Con_Date,">="&N($E15),Con_Date,"<="&AsOfDate),0)) -> 0 | J15: =IF(OR($A15="",$B15="",$F15=""),"",$F15+$H15-$I15) | K15: =IF(OR($J15="",N($G15)<=0),"",MAX(0,$J15)/$G15) | L15: =IF(OR($A15="",$B15=""),"",IF(COUNTIFS(CI_Site,$A15,CI_Mat,$B15)>1,"⚠ Duplicate site + material row",IF(ISNA(MATCH($B15,Mat_Code,0)),"⚠ Unknown material code",IF($E15="","⚠ Enter count date",IF($F15="","⚠ Enter beginning balance",IF(N($G15)<=0,"⚠ Enter storage capacity",IF($E15>AsOfDate,"⚠ Count date is after the As-of Date",IF($J15<0,"⚠ Negative stock – check logs or recount","OK")))))))) -> ⚠ Enter count date
A16: Gentri | B16: CEM | C16: =IF($B16="","",IFERROR(INDEX(Mat_Short,MATCH($B16,Mat_Code,0)),"⚠ Unknown code")) -> Cement | D16: =IF($B16="","",IFERROR(INDEX(Mat_Unit,MATCH($B16,Mat_Code,0)),"")) -> bags | H16: =IF(OR($A16="",$B16=""),"",SUMIFS(Del_Qty,Del_Site,$A16,Del_Mat,$B16,Del_Status,"Received",Del_Date,">="&N($E16),Del_Date,"<="&AsOfDate)) -> 0 | I16: =IF(OR($A16="",$B16=""),"",IFERROR(SUMIFS(INDEX(Con_Use,0,MATCH($B16,Mat_Code,0)),Con_Site,$A16,Con_Date,">="&N($E16),Con_Date,"<="&AsOfDate),0)) -> 0 | J16: =IF(OR($A16="",$B16="",$F16=""),"",$F16+$H16-$I16) | K16: =IF(OR($J16="",N($G16)<=0),"",MAX(0,$J16)/$G16) | L16: =IF(OR($A16="",$B16=""),"",IF(COUNTIFS(CI_Site,$A16,CI_Mat,$B16)>1,"⚠ Duplicate site + material row",IF(ISNA(MATCH($B16,Mat_Code,0)),"⚠ Unknown material code",IF($E16="","⚠ Enter count date",IF($F16="","⚠ Enter beginning balance",IF(N($G16)<=0,"⚠ Enter storage capacity",IF($E16>AsOfDate,"⚠ Count date is after the As-of Date",IF($J16<0,"⚠ Negative stock – check logs or recount","OK")))))))) -> ⚠ Enter count date
A17: Gentri | B17: SAND | C17: =IF($B17="","",IFERROR(INDEX(Mat_Short,MATCH($B17,Mat_Code,0)),"⚠ Unknown code")) -> Sand | D17: =IF($B17="","",IFERROR(INDEX(Mat_Unit,MATCH($B17,Mat_Code,0)),"")) -> m3 | H17: =IF(OR($A17="",$B17=""),"",SUMIFS(Del_Qty,Del_Site,$A17,Del_Mat,$B17,Del_Status,"Received",Del_Date,">="&N($E17),Del_Date,"<="&AsOfDate)) -> 0 | I17: =IF(OR($A17="",$B17=""),"",IFERROR(SUMIFS(INDEX(Con_Use,0,MATCH($B17,Mat_Code,0)),Con_Site,$A17,Con_Date,">="&N($E17),Con_Date,"<="&AsOfDate),0)) -> 0 | J17: =IF(OR($A17="",$B17="",$F17=""),"",$F17+$H17-$I17) | K17: =IF(OR($J17="",N($G17)<=0),"",MAX(0,$J17)/$G17) | L17: =IF(OR($A17="",$B17=""),"",IF(COUNTIFS(CI_Site,$A17,CI_Mat,$B17)>1,"⚠ Duplicate site + material row",IF(ISNA(MATCH($B17,Mat_Code,0)),"⚠ Unknown material code",IF($E17="","⚠ Enter count date",IF($F17="","⚠ Enter beginning balance",IF(N($G17)<=0,"⚠ Enter storage capacity",IF($E17>AsOfDate,"⚠ Count date is after the As-of Date",IF($J17<0,"⚠ Negative stock – check logs or recount","OK")))))))) -> ⚠ Enter count date
... A45: Batulao Impression | B45: ADM | C45: =IF($B45="","",IFERROR(INDEX(Mat_Short,MATCH($B45,Mat_Code,0)),"⚠ Unknown code")) -> Admixture | D45: =IF($B45="","",IFERROR(INDEX(Mat_Unit,MATCH($B45,Mat_Code,0)),"")) -> L | H45: =IF(OR($A45="",$B45=""),"",SUMIFS(Del_Qty,Del_Site,$A45,Del_Mat,$B45,Del_Status,"Received",Del_Date,">="&N($E45),Del_Date,"<="&AsOfDate)) -> 0 | I45: =IF(OR($A45="",$B45=""),"",IFERROR(SUMIFS(INDEX(Con_Use,0,MATCH($B45,Mat_Code,0)),Con_Site,$A45,Con_Date,">="&N($E45),Con_Date,"<="&AsOfDate),0)) -> 0 | J45: =IF(OR($A45="",$B45="",$F45=""),"",$F45+$H45-$I45) | K45: =IF(OR($J45="",N($G45)<=0),"",MAX(0,$J45)/$G45) | L45: =IF(OR($A45="",$B45=""),"",IF(COUNTIFS(CI_Site,$A45,CI_Mat,$B45)>1,"⚠ Duplicate site + material row",IF(ISNA(MATCH($B45,Mat_Code,0)),"⚠ Unknown material code",IF($E45="","⚠ Enter count date",IF($F45="","⚠ Enter beginning balance",IF(N($G45)<=0,"⚠ Enter storage capacity",IF($E45>AsOfDate,"⚠ Count date is after the As-of Date",IF($J45<0,"⚠ Negative stock – check logs or recount","OK")))))))) -> ⚠ Enter count date
C46: =IF($B46="","",IFERROR(INDEX(Mat_Short,MATCH($B46,Mat_Code,0)),"⚠ Unknown code")) | D46: =IF($B46="","",IFERROR(INDEX(Mat_Unit,MATCH($B46,Mat_Code,0)),"")) | H46: =IF(OR($A46="",$B46=""),"",SUMIFS(Del_Qty,Del_Site,$A46,Del_Mat,$B46,Del_Status,"Received",Del_Date,">="&N($E46),Del_Date,"<="&AsOfDate)) | I46: =IF(OR($A46="",$B46=""),"",IFERROR(SUMIFS(INDEX(Con_Use,0,MATCH($B46,Mat_Code,0)),Con_Site,$A46,Con_Date,">="&N($E46),Con_Date,"<="&AsOfDate),0)) | J46: =IF(OR($A46="",$B46="",$F46=""),"",$F46+$H46-$I46) | K46: =IF(OR($J46="",N($G46)<=0),"",MAX(0,$J46)/$G46) | L46: =IF(OR($A46="",$B46=""),"",IF(COUNTIFS(CI_Site,$A46,CI_Mat,$B46)>1,"⚠ Duplicate site + material row",IF(ISNA(MATCH($B46,Mat_Code,0)),"⚠ Unknown material code",IF($E46="","⚠ Enter count date",IF($F46="","⚠ Enter beginning balance",IF(N($G46)<=0,"⚠ Enter storage capacity",IF($E46>AsOfDate,"⚠ Count date is after the As-of Date",IF($J46<0,"⚠ Negative stock – check logs or recount","OK"))))))))
C47: =IF($B47="","",IFERROR(INDEX(Mat_Short,MATCH($B47,Mat_Code,0)),"⚠ Unknown code")) | D47: =IF($B47="","",IFERROR(INDEX(Mat_Unit,MATCH($B47,Mat_Code,0)),"")) | H47: =IF(OR($A47="",$B47=""),"",SUMIFS(Del_Qty,Del_Site,$A47,Del_Mat,$B47,Del_Status,"Received",Del_Date,">="&N($E47),Del_Date,"<="&AsOfDate)) | I47: =IF(OR($A47="",$B47=""),"",IFERROR(SUMIFS(INDEX(Con_Use,0,MATCH($B47,Mat_Code,0)),Con_Site,$A47,Con_Date,">="&N($E47),Con_Date,"<="&AsOfDate),0)) | J47: =IF(OR($A47="",$B47="",$F47=""),"",$F47+$H47-$I47) | K47: =IF(OR($J47="",N($G47)<=0),"",MAX(0,$J47)/$G47) | L47: =IF(OR($A47="",$B47=""),"",IF(COUNTIFS(CI_Site,$A47,CI_Mat,$B47)>1,"⚠ Duplicate site + material row",IF(ISNA(MATCH($B47,Mat_Code,0)),"⚠ Unknown material code",IF($E47="","⚠ Enter count date",IF($F47="","⚠ Enter beginning balance",IF(N($G47)<=0,"⚠ Enter storage capacity",IF($E47>AsOfDate,"⚠ Count date is after the As-of Date",IF($J47<0,"⚠ Negative stock – check logs or recount","OK"))))))))
C48: =IF($B48="","",IFERROR(INDEX(Mat_Short,MATCH($B48,Mat_Code,0)),"⚠ Unknown code")) | D48: =IF($B48="","",IFERROR(INDEX(Mat_Unit,MATCH($B48,Mat_Code,0)),"")) | H48: =IF(OR($A48="",$B48=""),"",SUMIFS(Del_Qty,Del_Site,$A48,Del_Mat,$B48,Del_Status,"Received",Del_Date,">="&N($E48),Del_Date,"<="&AsOfDate)) | I48: =IF(OR($A48="",$B48=""),"",IFERROR(SUMIFS(INDEX(Con_Use,0,MATCH($B48,Mat_Code,0)),Con_Site,$A48,Con_Date,">="&N($E48),Con_Date,"<="&AsOfDate),0)) | J48: =IF(OR($A48="",$B48="",$F48=""),"",$F48+$H48-$I48) | K48: =IF(OR($J48="",N($G48)<=0),"",MAX(0,$J48)/$G48) | L48: =IF(OR($A48="",$B48=""),"",IF(COUNTIFS(CI_Site,$A48,CI_Mat,$B48)>1,"⚠ Duplicate site + material row",IF(ISNA(MATCH($B48,Mat_Code,0)),"⚠ Unknown material code",IF($E48="","⚠ Enter count date",IF($F48="","⚠ Enter beginning balance",IF(N($G48)<=0,"⚠ Enter storage capacity",IF($E48>AsOfDate,"⚠ Count date is after the As-of Date",IF($J48<0,"⚠ Negative stock – check logs or recount","OK"))))))))
C49: =IF($B49="","",IFERROR(INDEX(Mat_Short,MATCH($B49,Mat_Code,0)),"⚠ Unknown code")) | D49: =IF($B49="","",IFERROR(INDEX(Mat_Unit,MATCH($B49,Mat_Code,0)),"")) | H49: =IF(OR($A49="",$B49=""),"",SUMIFS(Del_Qty,Del_Site,$A49,Del_Mat,$B49,Del_Status,"Received",Del_Date,">="&N($E49),Del_Date,"<="&AsOfDate)) | I49: =IF(OR($A49="",$B49=""),"",IFERROR(SUMIFS(INDEX(Con_Use,0,MATCH($B49,Mat_Code,0)),Con_Site,$A49,Con_Date,">="&N($E49),Con_Date,"<="&AsOfDate),0)) | J49: =IF(OR($A49="",$B49="",$F49=""),"",$F49+$H49-$I49) | K49: =IF(OR($J49="",N($G49)<=0),"",MAX(0,$J49)/$G49) | L49: =IF(OR($A49="",$B49=""),"",IF(COUNTIFS(CI_Site,$A49,CI_Mat,$B49)>1,"⚠ Duplicate site + material row",IF(ISNA(MATCH($B49,Mat_Code,0)),"⚠ Unknown material code",IF($E49="","⚠ Enter count date",IF($F49="","⚠ Enter beginning balance",IF(N($G49)<=0,"⚠ Enter storage capacity",IF($E49>AsOfDate,"⚠ Count date is after the As-of Date",IF($J49<0,"⚠ Negative stock – check logs or recount","OK"))))))))
C50: =IF($B50="","",IFERROR(INDEX(Mat_Short,MATCH($B50,Mat_Code,0)),"⚠ Unknown code")) | D50: =IF($B50="","",IFERROR(INDEX(Mat_Unit,MATCH($B50,Mat_Code,0)),"")) | H50: =IF(OR($A50="",$B50=""),"",SUMIFS(Del_Qty,Del_Site,$A50,Del_Mat,$B50,Del_Status,"Received",Del_Date,">="&N($E50),Del_Date,"<="&AsOfDate)) | I50: =IF(OR($A50="",$B50=""),"",IFERROR(SUMIFS(INDEX(Con_Use,0,MATCH($B50,Mat_Code,0)),Con_Site,$A50,Con_Date,">="&N($E50),Con_Date,"<="&AsOfDate),0)) | J50: =IF(OR($A50="",$B50="",$F50=""),"",$F50+$H50-$I50) | K50: =IF(OR($J50="",N($G50)<=0),"",MAX(0,$J50)/$G50) | L50: =IF(OR($A50="",$B50=""),"",IF(COUNTIFS(CI_Site,$A50,CI_Mat,$B50)>1,"⚠ Duplicate site + material row",IF(ISNA(MATCH($B50,Mat_Code,0)),"⚠ Unknown material code",IF($E50="","⚠ Enter count date",IF($F50="","⚠ Enter beginning balance",IF(N($G50)<=0,"⚠ Enter storage capacity",IF($E50>AsOfDate,"⚠ Count date is after the As-of Date",IF($J50<0,"⚠ Negative stock – check logs or recount","OK"))))))))
C51: =IF($B51="","",IFERROR(INDEX(Mat_Short,MATCH($B51,Mat_Code,0)),"⚠ Unknown code")) | D51: =IF($B51="","",IFERROR(INDEX(Mat_Unit,MATCH($B51,Mat_Code,0)),"")) | H51: =IF(OR($A51="",$B51=""),"",SUMIFS(Del_Qty,Del_Site,$A51,Del_Mat,$B51,Del_Status,"Received",Del_Date,">="&N($E51),Del_Date,"<="&AsOfDate)) | I51: =IF(OR($A51="",$B51=""),"",IFERROR(SUMIFS(INDEX(Con_Use,0,MATCH($B51,Mat_Code,0)),Con_Site,$A51,Con_Date,">="&N($E51),Con_Date,"<="&AsOfDate),0)) | J51: =IF(OR($A51="",$B51="",$F51=""),"",$F51+$H51-$I51) | K51: =IF(OR($J51="",N($G51)<=0),"",MAX(0,$J51)/$G51) | L51: =IF(OR($A51="",$B51=""),"",IF(COUNTIFS(CI_Site,$A51,CI_Mat,$B51)>1,"⚠ Duplicate site + material row",IF(ISNA(MATCH($B51,Mat_Code,0)),"⚠ Unknown material code",IF($E51="","⚠ Enter count date",IF($F51="","⚠ Enter beginning balance",IF(N($G51)<=0,"⚠ Enter storage capacity",IF($E51>AsOfDate,"⚠ Count date is after the As-of Date",IF($J51<0,"⚠ Negative stock – check logs or recount","OK"))))))))
C52: =IF($B52="","",IFERROR(INDEX(Mat_Short,MATCH($B52,Mat_Code,0)),"⚠ Unknown code")) | D52: =IF($B52="","",IFERROR(INDEX(Mat_Unit,MATCH($B52,Mat_Code,0)),"")) | H52: =IF(OR($A52="",$B52=""),"",SUMIFS(Del_Qty,Del_Site,$A52,Del_Mat,$B52,Del_Status,"Received",Del_Date,">="&N($E52),Del_Date,"<="&AsOfDate)) | I52: =IF(OR($A52="",$B52=""),"",IFERROR(SUMIFS(INDEX(Con_Use,0,MATCH($B52,Mat_Code,0)),Con_Site,$A52,Con_Date,">="&N($E52),Con_Date,"<="&AsOfDate),0)) | J52: =IF(OR($A52="",$B52="",$F52=""),"",$F52+$H52-$I52) | K52: =IF(OR($J52="",N($G52)<=0),"",MAX(0,$J52)/$G52) | L52: =IF(OR($A52="",$B52=""),"",IF(COUNTIFS(CI_Site,$A52,CI_Mat,$B52)>1,"⚠ Duplicate site + material row",IF(ISNA(MATCH($B52,Mat_Code,0)),"⚠ Unknown material code",IF($E52="","⚠ Enter count date",IF($F52="","⚠ Enter beginning balance",IF(N($G52)<=0,"⚠ Enter storage capacity",IF($E52>AsOfDate,"⚠ Count date is after the As-of Date",IF($J52<0,"⚠ Negative stock – check logs or recount","OK"))))))))
C53: =IF($B53="","",IFERROR(INDEX(Mat_Short,MATCH($B53,Mat_Code,0)),"⚠ Unknown code")) | D53: =IF($B53="","",IFERROR(INDEX(Mat_Unit,MATCH($B53,Mat_Code,0)),"")) | H53: =IF(OR($A53="",$B53=""),"",SUMIFS(Del_Qty,Del_Site,$A53,Del_Mat,$B53,Del_Status,"Received",Del_Date,">="&N($E53),Del_Date,"<="&AsOfDate)) | I53: =IF(OR($A53="",$B53=""),"",IFERROR(SUMIFS(INDEX(Con_Use,0,MATCH($B53,Mat_Code,0)),Con_Site,$A53,Con_Date,">="&N($E53),Con_Date,"<="&AsOfDate),0)) | J53: =IF(OR($A53="",$B53="",$F53=""),"",$F53+$H53-$I53) | K53: =IF(OR($J53="",N($G53)<=0),"",MAX(0,$J53)/$G53) | L53: =IF(OR($A53="",$B53=""),"",IF(COUNTIFS(CI_Site,$A53,CI_Mat,$B53)>1,"⚠ Duplicate site + material row",IF(ISNA(MATCH($B53,Mat_Code,0)),"⚠ Unknown material code",IF($E53="","⚠ Enter count date",IF($F53="","⚠ Enter beginning balance",IF(N($G53)<=0,"⚠ Enter storage capacity",IF($E53>AsOfDate,"⚠ Count date is after the As-of Date",IF($J53<0,"⚠ Negative stock – check logs or recount","OK"))))))))
C54: =IF($B54="","",IFERROR(INDEX(Mat_Short,MATCH($B54,Mat_Code,0)),"⚠ Unknown code")) | D54: =IF($B54="","",IFERROR(INDEX(Mat_Unit,MATCH($B54,Mat_Code,0)),"")) | H54: =IF(OR($A54="",$B54=""),"",SUMIFS(Del_Qty,Del_Site,$A54,Del_Mat,$B54,Del_Status,"Received",Del_Date,">="&N($E54),Del_Date,"<="&AsOfDate)) | I54: =IF(OR($A54="",$B54=""),"",IFERROR(SUMIFS(INDEX(Con_Use,0,MATCH($B54,Mat_Code,0)),Con_Site,$A54,Con_Date,">="&N($E54),Con_Date,"<="&AsOfDate),0)) | J54: =IF(OR($A54="",$B54="",$F54=""),"",$F54+$H54-$I54) | K54: =IF(OR($J54="",N($G54)<=0),"",MAX(0,$J54)/$G54) | L54: =IF(OR($A54="",$B54=""),"",IF(COUNTIFS(CI_Site,$A54,CI_Mat,$B54)>1,"⚠ Duplicate site + material row",IF(ISNA(MATCH($B54,Mat_Code,0)),"⚠ Unknown material code",IF($E54="","⚠ Enter count date",IF($F54="","⚠ Enter beginning balance",IF(N($G54)<=0,"⚠ Enter storage capacity",IF($E54>AsOfDate,"⚠ Count date is after the As-of Date",IF($J54<0,"⚠ Negative stock – check logs or recount","OK"))))))))
C55: =IF($B55="","",IFERROR(INDEX(Mat_Short,MATCH($B55,Mat_Code,0)),"⚠ Unknown code")) | D55: =IF($B55="","",IFERROR(INDEX(Mat_Unit,MATCH($B55,Mat_Code,0)),"")) | H55: =IF(OR($A55="",$B55=""),"",SUMIFS(Del_Qty,Del_Site,$A55,Del_Mat,$B55,Del_Status,"Received",Del_Date,">="&N($E55),Del_Date,"<="&AsOfDate)) | I55: =IF(OR($A55="",$B55=""),"",IFERROR(SUMIFS(INDEX(Con_Use,0,MATCH($B55,Mat_Code,0)),Con_Site,$A55,Con_Date,">="&N($E55),Con_Date,"<="&AsOfDate),0)) | J55: =IF(OR($A55="",$B55="",$F55=""),"",$F55+$H55-$I55) | K55: =IF(OR($J55="",N($G55)<=0),"",MAX(0,$J55)/$G55) | L55: =IF(OR($A55="",$B55=""),"",IF(COUNTIFS(CI_Site,$A55,CI_Mat,$B55)>1,"⚠ Duplicate site + material row",IF(ISNA(MATCH($B55,Mat_Code,0)),"⚠ Unknown material code",IF($E55="","⚠ Enter count date",IF($F55="","⚠ Enter beginning balance",IF(N($G55)<=0,"⚠ Enter storage capacity",IF($E55>AsOfDate,"⚠ Count date is after the As-of Date",IF($J55<0,"⚠ Negative stock – check logs or recount","OK"))))))))
C56: =IF($B56="","",IFERROR(INDEX(Mat_Short,MATCH($B56,Mat_Code,0)),"⚠ Unknown code")) | D56: =IF($B56="","",IFERROR(INDEX(Mat_Unit,MATCH($B56,Mat_Code,0)),"")) | H56: =IF(OR($A56="",$B56=""),"",SUMIFS(Del_Qty,Del_Site,$A56,Del_Mat,$B56,Del_Status,"Received",Del_Date,">="&N($E56),Del_Date,"<="&AsOfDate)) | I56: =IF(OR($A56="",$B56=""),"",IFERROR(SUMIFS(INDEX(Con_Use,0,MATCH($B56,Mat_Code,0)),Con_Site,$A56,Con_Date,">="&N($E56),Con_Date,"<="&AsOfDate),0)) | J56: =IF(OR($A56="",$B56="",$F56=""),"",$F56+$H56-$I56) | K56: =IF(OR($J56="",N($G56)<=0),"",MAX(0,$J56)/$G56) | L56: =IF(OR($A56="",$B56=""),"",IF(COUNTIFS(CI_Site,$A56,CI_Mat,$B56)>1,"⚠ Duplicate site + material row",IF(ISNA(MATCH($B56,Mat_Code,0)),"⚠ Unknown material code",IF($E56="","⚠ Enter count date",IF($F56="","⚠ Enter beginning balance",IF(N($G56)<=0,"⚠ Enter storage capacity",IF($E56>AsOfDate,"⚠ Count date is after the As-of Date",IF($J56<0,"⚠ Negative stock – check logs or recount","OK"))))))))
C57: =IF($B57="","",IFERROR(INDEX(Mat_Short,MATCH($B57,Mat_Code,0)),"⚠ Unknown code")) | D57: =IF($B57="","",IFERROR(INDEX(Mat_Unit,MATCH($B57,Mat_Code,0)),"")) | H57: =IF(OR($A57="",$B57=""),"",SUMIFS(Del_Qty,Del_Site,$A57,Del_Mat,$B57,Del_Status,"Received",Del_Date,">="&N($E57),Del_Date,"<="&AsOfDate)) | I57: =IF(OR($A57="",$B57=""),"",IFERROR(SUMIFS(INDEX(Con_Use,0,MATCH($B57,Mat_Code,0)),Con_Site,$A57,Con_Date,">="&N($E57),Con_Date,"<="&AsOfDate),0)) | J57: =IF(OR($A57="",$B57="",$F57=""),"",$F57+$H57-$I57) | K57: =IF(OR($J57="",N($G57)<=0),"",MAX(0,$J57)/$G57) | L57: =IF(OR($A57="",$B57=""),"",IF(COUNTIFS(CI_Site,$A57,CI_Mat,$B57)>1,"⚠ Duplicate site + material row",IF(ISNA(MATCH($B57,Mat_Code,0)),"⚠ Unknown material code",IF($E57="","⚠ Enter count date",IF($F57="","⚠ Enter beginning balance",IF(N($G57)<=0,"⚠ Enter storage capacity",IF($E57>AsOfDate,"⚠ Count date is after the As-of Date",IF($J57<0,"⚠ Negative stock – check logs or recount","OK"))))))))
... C105: =IF($B105="","",IFERROR(INDEX(Mat_Short,MATCH($B105,Mat_Code,0)),"⚠ Unknown code")) | D105: =IF($B105="","",IFERROR(INDEX(Mat_Unit,MATCH($B105,Mat_Code,0)),"")) | H105: =IF(OR($A105="",$B105=""),"",SUMIFS(Del_Qty,Del_Site,$A105,Del_Mat,$B105,Del_Status,"Received",Del_Date,">="&N($E105),Del_Date,"<="&AsOfDate)) | I105: =IF(OR($A105="",$B105=""),"",IFERROR(SUMIFS(INDEX(Con_Use,0,MATCH($B105,Mat_Code,0)),Con_Site,$A105,Con_Date,">="&N($E105),Con_Date,"<="&AsOfDate),0)) | J105: =IF(OR($A105="",$B105="",$F105=""),"",$F105+$H105-$I105) | K105: =IF(OR($J105="",N($G105)<=0),"",MAX(0,$J105)/$G105) | L105: =IF(OR($A105="",$B105=""),"",IF(COUNTIFS(CI_Site,$A105,CI_Mat,$B105)>1,"⚠ Duplicate site + material row",IF(ISNA(MATCH($B105,Mat_Code,0)),"⚠ Unknown material code",IF($E105="","⚠ Enter count date",IF($F105="","⚠ Enter beginning balance",IF(N($G105)<=0,"⚠ Enter storage capacity",IF($E105>AsOfDate,"⚠ Count date is after the As-of Date",IF($J105<0,"⚠ Negative stock – check logs or recount","OK"))))))))

Sheet Consumption Log
A1: 2 · Consumption Log — Concrete Produced (m3) by Mix Design
A2: Declare the m3 of concrete produced per day (or per pour/shift). Material used = m3 × mix design quantity × (1 + allowance), and is deducted from stock automatically.
A4: Date | B4: Site / Project | C4: Mix Code | D4: Concrete Produced (m3) | E4: Mix Description | F4: =Settings!$C$11&" used"&CHAR(10)&"("&Settings!$E$11&")" -> Cement used (bags) | G4: =Settings!$C$12&" used"&CHAR(10)&"("&Settings!$E$12&")" -> Sand used (m3) | H4: =Settings!$C$13&" used"&CHAR(10)&"("&Settings!$E$13&")" -> Gravel 3/4" used (m3) | I4: =Settings!$C$14&" used"&CHAR(10)&"("&Settings!$E$14&")" -> Gravel 3/8" used (m3) | J4: =Settings!$C$15&" used"&CHAR(10)&"("&Settings!$E$15&")" -> Admixture used (L) | K4: Element / Remarks | L4: Check
A5: 46296 | B5: Example Site | C5: MD-01 | D5: 18.5 | E5: Precast Wall Panel | F5: (auto) | G5: (auto) | H5: (auto) | I5: (auto) | J5: (auto) | K5: Example row — wall panels, casting beds 1-3
E6: =IF($C6="","",IFERROR(INDEX(Mix_Desc,MATCH($C6,Mix_Code,0)),"⚠ Unknown mix code")) | F6: =IF(OR($C6="",$D6=""),"",IFERROR($D6*INDEX(Mix_Eff,MATCH($C6,Mix_Code,0),1),"")) | G6: =IF(OR($C6="",$D6=""),"",IFERROR($D6*INDEX(Mix_Eff,MATCH($C6,Mix_Code,0),2),"")) | H6: =IF(OR($C6="",$D6=""),"",IFERROR($D6*INDEX(Mix_Eff,MATCH($C6,Mix_Code,0),3),"")) | I6: =IF(OR($C6="",$D6=""),"",IFERROR($D6*INDEX(Mix_Eff,MATCH($C6,Mix_Code,0),4),"")) | J6: =IF(OR($C6="",$D6=""),"",IFERROR($D6*INDEX(Mix_Eff,MATCH($C6,Mix_Code,0),5),"")) | L6: =IF(AND($A6="",$B6="",$C6="",$D6=""),"",IF($A6="","⚠ Date missing",IF($B6="","⚠ Site missing",IF(ISNA(MATCH($C6,Mix_Code,0)),"⚠ Unknown mix code",IF($D6="","⚠ Enter m3 produced",IF(COUNTIF(CI_Site,$B6)=0,"⚠ Site not set up in Current Inventory",IF($A6>AsOfDate,"Future date – not yet deducted","OK")))))))
E7: =IF($C7="","",IFERROR(INDEX(Mix_Desc,MATCH($C7,Mix_Code,0)),"⚠ Unknown mix code")) | F7: =IF(OR($C7="",$D7=""),"",IFERROR($D7*INDEX(Mix_Eff,MATCH($C7,Mix_Code,0),1),"")) | G7: =IF(OR($C7="",$D7=""),"",IFERROR($D7*INDEX(Mix_Eff,MATCH($C7,Mix_Code,0),2),"")) | H7: =IF(OR($C7="",$D7=""),"",IFERROR($D7*INDEX(Mix_Eff,MATCH($C7,Mix_Code,0),3),"")) | I7: =IF(OR($C7="",$D7=""),"",IFERROR($D7*INDEX(Mix_Eff,MATCH($C7,Mix_Code,0),4),"")) | J7: =IF(OR($C7="",$D7=""),"",IFERROR($D7*INDEX(Mix_Eff,MATCH($C7,Mix_Code,0),5),"")) | L7: =IF(AND($A7="",$B7="",$C7="",$D7=""),"",IF($A7="","⚠ Date missing",IF($B7="","⚠ Site missing",IF(ISNA(MATCH($C7,Mix_Code,0)),"⚠ Unknown mix code",IF($D7="","⚠ Enter m3 produced",IF(COUNTIF(CI_Site,$B7)=0,"⚠ Site not set up in Current Inventory",IF($A7>AsOfDate,"Future date – not yet deducted","OK")))))))
